Workbook
Name apagar: #REF!,#REF!,#REF!,#REF!,#REF!,#REF!,#REF!,#REF!,#REF!,#REF!,#REF!,#REF!,#REF!,#REF!,#REF!,#REF!,#REF!,#REF!
Name apagartudo: #REF!,#REF!,#REF!,#REF!,#REF!,#REF!,#REF!,#REF!,#REF!,#REF!,#REF!,#REF!,#REF!,#REF!,#REF!,#REF!,#REF!,#REF!
Name limpar: #REF!,#REF!,#REF!,#REF!,#REF!,#REF!,#REF!,#REF!,#REF!,#REF!,#REF!,#REF!,#REF!,#REF!,#REF!,#REF!,#REF!,#REF!,#REF!,#REF!

Sheet MENU
C50: Copyright © 2017 Romica Brasil Ltda. Todos os direitos reservados.

Sheet Matéria prima
B1: Margarina Ricca | F1: Margarina Sina BB | J1: Margarina Sina SA | N1: Margarina Dekel | R1: Gordura Dekel | V1: Leite em Pó Composto | Z1: Leite em Pó Integral | AD1: Amido de Milho | AH1: Embalagem 1kg | AL1: Embalagem 500g
A2: Data | B2: NF | C2: Ent | D2: Saída | E2: Saldo | F2: NF | G2: Ent | H2: Saída | I2: Saldo | J2: NF | K2: Ent | L2: Saída | M2: Saldo | N2: NF | O2: Ent | P2: Saída | Q2: Saldo | R2: NF | S2: Ent | T2: Saída | U2: Saldo | V2: NF | W2: Ent | X2: Saída | Y2: Saldo | Z2: NF | AA2: Ent | AB2: Saída | AC2: Saldo | AD2: NF | AE2: Ent | AF2: Saída | AG2: Saldo | AH2: NF | AI2: Ent | AJ2: Saída | AK2: Saldo | AL2: NF | AM2: Ent | AN2: Saída | AO2: Saldo | AQ2: Resumo Matéria-Prima
A3: 1 | C3: 152 | E3: =(0+C3)-D3 -> 152 | I3: =(0+G3)-H3 -> 0 | M3: =(0+K3)-L3 -> 0 | O3: 11 | Q3: =(0+O3)-P3 -> 11 | S3: 32 | U3: =(0+S3)-T3 -> 32 | W3: 14 | Y3: =(0+W3)-X3 -> 14 | AA3: 33 | AC3: =(0+AA3)-AB3 -> 33 | AE3: 16 | AG3: =(0+AE3)-AF3 -> 16 | AI3: 29 | AK3: =(0+AI3)-AJ3 -> 29 | AM3: 6 | AO3: =(0+AM3)-AN3 -> 6 | AQ3: =B1 -> Margarina Ricca | AR3: =E34 -> 100
A4: 2 | E4: =(E3+C4)-D4 -> 152 | I4: =(I3+G4)-H4 -> 0 | M4: =(M3+K4)-L4 -> 0 | Q4: =(Q3+O4)-P4 -> 11 | U4: =(U3+S4)-T4 -> 32 | Y4: =(Y3+W4)-X4 -> 14 | AC4: =(AC3+AA4)-AB4 -> 33 | AG4: =(AG3+AE4)-AF4 -> 16 | AK4: =(AK3+AI4)-AJ4 -> 29 | AO4: =(AO3+AM4)-AN4 -> 6 | AQ4: =F1 -> Margarina Sina BB | AR4: =I34 -> 26
A5: 3 | E5: =(E4+C5)-D5 -> 152 | I5: =(I4+G5)-H5 -> 0 | M5: =(M4+K5)-L5 -> 0 | Q5: =(Q4+O5)-P5 -> 11 | U5: =(U4+S5)-T5 -> 32 | Y5: =(Y4+W5)-X5 -> 14 | AC5: =(AC4+AA5)-AB5 -> 33 | AG5: =(AG4+AE5)-AF5 -> 16 | AK5: =(AK4+AI5)-AJ5 -> 29 | AO5: =(AO4+AM5)-AN5 -> 6 | AQ5: =J1 -> Margarina Sina SA | AR5: =M34 -> 0
A6: 4 | E6: =(E5+C6)-D6 -> 152 | I6: =(I5+G6)-H6 -> 0 | M6: =(M5+K6)-L6 -> 0 | Q6: =(Q5+O6)-P6 -> 11 | U6: =(U5+S6)-T6 -> 32 | Y6: =(Y5+W6)-X6 -> 14 | AC6: =(AC5+AA6)-AB6 -> 33 | AG6: =(AG5+AE6)-AF6 -> 16 | AK6: =(AK5+AI6)-AJ6 -> 29 | AO6: =(AO5+AM6)-AN6 -> 6 | AQ6: =N1 -> Margarina Dekel | AR6: =Q34 -> 36
A7: 5 | E7: =(E6+C7)-D7 -> 152 | I7: =(I6+G7)-H7 -> 0 | M7: =(M6+K7)-L7 -> 0 | Q7: =(Q6+O7)-P7 -> 11 | U7: =(U6+S7)-T7 -> 32 | Y7: =(Y6+W7)-X7 -> 14 | AC7: =(AC6+AA7)-AB7 -> 33 | AG7: =(AG6+AE7)-AF7 -> 16 | AK7: =(AK6+AI7)-AJ7 -> 29 | AO7: =(AO6+AM7)-AN7 -> 6 | AQ7: =R1 -> Gordura Dekel | AR7: =U34 -> 48
A8: 6 | E8: =(E7+C8)-D8 -> 152 | I8: =(I7+G8)-H8 -> 0 | M8: =(M7+K8)-L8 -> 0 | Q8: =(Q7+O8)-P8 -> 11 | U8: =(U7+S8)-T8 -> 32 | Y8: =(Y7+W8)-X8 -> 14 | AC8: =(AC7+AA8)-AB8 -> 33 | AG8: =(AG7+AE8)-AF8 -> 16 | AK8: =(AK7+AI8)-AJ8 -> 29 | AO8: =(AO7+AM8)-AN8 -> 6 | AQ8: =V1 -> Leite em Pó Composto | AR8: =Y34 -> 12
A9: 7 | D9: 9 | E9: =(E8+C9)-D9 -> 143 | I9: =(I8+G9)-H9 -> 0 | M9: =(M8+K9)-L9 -> 0 | P9: 2 | Q9: =(Q8+O9)-P9 -> 9 | T9: 4 | U9: =(U8+S9)-T9 -> 28 | Y9: =(Y8+W9)-X9 -> 14 | AB9: 1 | AC9: =(AC8+AA9)-AB9 -> 32 | AF9: 1 | AG9: =(AG8+AE9)-AF9 -> 15 | AJ9: 1 | AK9: =(AK8+AI9)-AJ9 -> 28 | AO9: =(AO8+AM9)-AN9 -> 6 | AQ9: =Z1 -> Leite em Pó Integral | AR9: =AC34 -> 27
A10: 8 | D10: 8 | E10: =(E9+C10)-D10 -> 135 | I10: =(I9+G10)-H10 -> 0 | M10: =(M9+K10)-L10 -> 0 | P10: 8 | Q10: =(Q9+O10)-P10 -> 1 | U10: =(U9+S10)-T10 -> 28 | X10: 1 | Y10: =(Y9+W10)-X10 -> 13 | AC10: =(AC9+AA10)-AB10 -> 32 | AF10: 1 | AG10: =(AG9+AE10)-AF10 -> 14 | AK10: =(AK9+AI10)-AJ10 -> 28 | AO10: =(AO9+AM10)-AN10 -> 6 | AQ10: =AD1 -> Amido de Milho | AR10: =AG34 -> 8
A11: 9 | E11: =(E10+C11)-D11 -> 135 | I11: =(I10+G11)-H11 -> 0 | M11: =(M10+K11)-L11 -> 0 | Q11: =(Q10+O11)-P11 -> 1 | U11: =(U10+S11)-T11 -> 28 | Y11: =(Y10+W11)-X11 -> 13 | AC11: =(AC10+AA11)-AB11 -> 32 | AG11: =(AG10+AE11)-AF11 -> 14 | AK11: =(AK10+AI11)-AJ11 -> 28 | AO11: =(AO10+AM11)-AN11 -> 6 | AQ11: =AH1 -> Embalagem 1kg | AR11: =AK34 -> 25
A12: 10 | E12: =(E11+C12)-D12 -> 135 | I12: =(I11+G12)-H12 -> 0 | M12: =(M11+K12)-L12 -> 0 | Q12: =(Q11+O12)-P12 -> 1 | U12: =(U11+S12)-T12 -> 28 | Y12: =(Y11+W12)-X12 -> 13 | AC12: =(AC11+AA12)-AB12 -> 32 | AG12: =(AG11+AE12)-AF12 -> 14 | AK12: =(AK11+AI12)-AJ12 -> 28 | AO12: =(AO11+AM12)-AN12 -> 6 | AQ12: =AL1 -> Embalagem 500g | AR12: =AO34 -> 6
A13: 11 | E13: =(E12+C13)-D13 -> 135 | I13: =(I12+G13)-H13 -> 0 | M13: =(M12+K13)-L13 -> 0 | Q13: =(Q12+O13)-P13 -> 1 | U13: =(U12+S13)-T13 -> 28 | Y13: =(Y12+W13)-X13 -> 13 | AC13: =(AC12+AA13)-AB13 -> 32 | AG13: =(AG12+AE13)-AF13 -> 14 | AK13: =(AK12+AI13)-AJ13 -> 28 | AO13: =(AO12+AM13)-AN13 -> 6
A14: 12 | D14: 10 | E14: =(E13+C14)-D14 -> 125 | I14: =(I13+G14)-H14 -> 0 | M14: =(M13+K14)-L14 -> 0 | P14: 1 | Q14: =(Q13+O14)-P14 -> 0 | T14: 4 | U14: =(U13+S14)-T14 -> 24 | Y14: =(Y13+W14)-X14 -> 13 | AB14: 1 | AC14: =(AC13+AA14)-AB14 -> 31 | AF14: 1 | AG14: =(AG13+AE14)-AF14 -> 13 | AJ14: 1 | AK14: =(AK13+AI14)-AJ14 -> 27 | AO14: =(AO13+AM14)-AN14 -> 6
A15: 13 | E15: =(E14+C15)-D15 -> 125 | I15: =(I14+G15)-H15 -> 0 | M15: =(M14+K15)-L15 -> 0 | Q15: =(Q14+O15)-P15 -> 0 | U15: =(U14+S15)-T15 -> 24 | Y15: =(Y14+W15)-X15 -> 13 | AC15: =(AC14+AA15)-AB15 -> 31 | AG15: =(AG14+AE15)-AF15 -> 13 | AK15: =(AK14+AI15)-AJ15 -> 27 | AO15: =(AO14+AM15)-AN15 -> 6
A16: 14 | D16: 11 | E16: =(E15+C16)-D16 -> 114 | G16: 40 | I16: =(I15+G16)-H16 -> 40 | M16: =(M15+K16)-L16 -> 0 | O16: 40 | Q16: =(Q15+O16)-P16 -> 40 | S16: 40 | T16: 4 | U16: =(U15+S16)-T16 -> 60 | Y16: =(Y15+W16)-X16 -> 13 | AB16: 1 | AC16: =(AC15+AA16)-AB16 -> 30 | AF16: 1 | AG16: =(AG15+AE16)-AF16 -> 12 | AK16: =(AK15+AI16)-AJ16 -> 27 | AO16: =(AO15+AM16)-AN16 -> 6
A17: 15 | E17: =(E16+C17)-D17 -> 114 | I17: =(I16+G17)-H17 -> 40 | M17: =(M16+K17)-L17 -> 0 | Q17: =(Q16+O17)-P17 -> 40 | U17: =(U16+S17)-T17 -> 60 | Y17: =(Y16+W17)-X17 -> 13 | AC17: =(AC16+AA17)-AB17 -> 30 | AG17: =(AG16+AE17)-AF17 -> 12 | AK17: =(AK16+AI17)-AJ17 -> 27 | AO17: =(AO16+AM17)-AN17 -> 6
A18: 16 | E18: =(E17+C18)-D18 -> 114 | I18: =(I17+G18)-H18 -> 40 | M18: =(M17+K18)-L18 -> 0 | Q18: =(Q17+O18)-P18 -> 40 | U18: =(U17+S18)-T18 -> 60 | Y18: =(Y17+W18)-X18 -> 13 | AC18: =(AC17+AA18)-AB18 -> 30 | AG18: =(AG17+AE18)-AF18 -> 12 | AK18: =(AK17+AI18)-AJ18 -> 27 | AO18: =(AO17+AM18)-AN18 -> 6
A19: 17 | E19: =(E18+C19)-D19 -> 114 | I19: =(I18+G19)-H19 -> 40 | M19: =(M18+K19)-L19 -> 0 | Q19: =(Q18+O19)-P19 -> 40 | U19: =(U18+S19)-T19 -> 60 | Y19: =(Y18+W19)-X19 -> 13 | AC19: =(AC18+AA19)-AB19 -> 30 | AG19: =(AG18+AE19)-AF19 -> 12 | AK19: =(AK18+AI19)-AJ19 -> 27 | AO19: =(AO18+AM19)-AN19 -> 6
A20: 18 | E20: =(E19+C20)-D20 -> 114 | I20: =(I19+G20)-H20 -> 40 | M20: =(M19+K20)-L20 -> 0 | Q20: =(Q19+O20)-P20 -> 40 | U20: =(U19+S20)-T20 -> 60 | Y20: =(Y19+W20)-X20 -> 13 | AC20: =(AC19+AA20)-AB20 -> 30 | AG20: =(AG19+AE20)-AF20 -> 12 | AK20: =(AK19+AI20)-AJ20 -> 27 | AO20: =(AO19+AM20)-AN20 -> 6
A21: 19 | E21: =(E20+C21)-D21 -> 114 | I21: =(I20+G21)-H21 -> 40 | M21: =(M20+K21)-L21 -> 0 | Q21: =(Q20+O21)-P21 -> 40 | U21: =(U20+S21)-T21 -> 60 | Y21: =(Y20+W21)-X21 -> 13 | AC21: =(AC20+AA21)-AB21 -> 30 | AG21: =(AG20+AE21)-AF21 -> 12 | AK21: =(AK20+AI21)-AJ21 -> 27 | AO21: =(AO20+AM21)-AN21 -> 6
A22: 20 | D22: 8 | E22: =(E21+C22)-D22 -> 106 | H22: 3 | I22: =(I21+G22)-H22 -> 37 | M22: =(M21+K22)-L22 -> 0 | Q22: =(Q21+O22)-P22 -> 40 | T22: 4 | U22: =(U21+S22)-T22 -> 56 | Y22: =(Y21+W22)-X22 -> 13 | AB22: 1 | AC22: =(AC21+AA22)-AB22 -> 29 | AF22: 1 | AG22: =(AG21+AE22)-AF22 -> 11 | AJ22: 1 | AK22: =(AK21+AI22)-AJ22 -> 26 | AO22: =(AO21+AM22)-AN22 -> 6
A23: 21 | E23: =(E22+C23)-D23 -> 106 | I23: =(I22+G23)-H23 -> 37 | M23: =(M22+K23)-L23 -> 0 | Q23: =(Q22+O23)-P23 -> 40 | U23: =(U22+S23)-T23 -> 56 | Y23: =(Y22+W23)-X23 -> 13 | AC23: =(AC22+AA23)-AB23 -> 29 | AG23: =(AG22+AE23)-AF23 -> 11 | AK23: =(AK22+AI23)-AJ23 -> 26 | AO23: =(AO22+AM23)-AN23 -> 6
A24: 22 | D24: 8 | E24: =(E23+C24)-D24 -> 98 | H24: 3 | I24: =(I23+G24)-H24 -> 34 | M24: =(M23+K24)-L24 -> 0 | Q24: =(Q23+O24)-P24 -> 40 | T24: 4 | U24: =(U23+S24)-T24 -> 52 | Y24: =(Y23+W24)-X24 -> 13 | AB24: 1 | AC24: =(AC23+AA24)-AB24 -> 28 | AF24: 1 | AG24: =(AG23+AE24)-AF24 -> 10 | AK24: =(AK23+AI24)-AJ24 -> 26 | AO24: =(AO23+AM24)-AN24 -> 6
A25: 23 | E25: =(E24+C25)-D25 -> 98 | I25: =(I24+G25)-H25 -> 34 | M25: =(M24+K25)-L25 -> 0 | Q25: =(Q24+O25)-P25 -> 40 | U25: =(U24+S25)-T25 -> 52 | Y25: =(Y24+W25)-X25 -> 13 | AC25: =(AC24+AA25)-AB25 -> 28 | AG25: =(AG24+AE25)-AF25 -> 10 | AK25: =(AK24+AI25)-AJ25 -> 26 | AO25: =(AO24+AM25)-AN25 -> 6
A26: 24 | E26: =(E25+C26)-D26 -> 98 | I26: =(I25+G26)-H26 -> 34 | M26: =(M25+K26)-L26 -> 0 | Q26: =(Q25+O26)-P26 -> 40 | U26: =(U25+S26)-T26 -> 52 | Y26: =(Y25+W26)-X26 -> 13 | AC26: =(AC25+AA26)-AB26 -> 28 | AG26: =(AG25+AE26)-AF26 -> 10 | AK26: =(AK25+AI26)-AJ26 -> 26 | AO26: =(AO25+AM26)-AN26 -> 6
A27: 25 | E27: =(E26+C27)-D27 -> 98 | I27: =(I26+G27)-H27 -> 34 | M27: =(M26+K27)-L27 -> 0 | Q27: =(Q26+O27)-P27 -> 40 | U27: =(U26+S27)-T27 -> 52 | Y27: =(Y26+W27)-X27 -> 13 | AC27: =(AC26+AA27)-AB27 -> 28 | AG27: =(AG26+AE27)-AF27 -> 10 | AK27: =(AK26+AI27)-AJ27 -> 26 | AO27: =(AO26+AM27)-AN27 -> 6
A28: 26 | E28: =(E27+C28)-D28 -> 98 | I28: =(I27+G28)-H28 -> 34 | M28: =(M27+K28)-L28 -> 0 | Q28: =(Q27+O28)-P28 -> 40 | U28: =(U27+S28)-T28 -> 52 | Y28: =(Y27+W28)-X28 -> 13 | AC28: =(AC27+AA28)-AB28 -> 28 | AG28: =(AG27+AE28)-AF28 -> 10 | AK28: =(AK27+AI28)-AJ28 -> 26 | AO28: =(AO27+AM28)-AN28 -> 6
A29: 27 | C29: 10 | D29: 8 | E29: =(E28+C29)-D29 -> 100 | H29: 3 | I29: =(I28+G29)-H29 -> 31 | M29: =(M28+K29)-L29 -> 0 | Q29: =(Q28+O29)-P29 -> 40 | T29: 4 | U29: =(U28+S29)-T29 -> 48 | Y29: =(Y28+W29)-X29 -> 13 | AB29: 1 | AC29: =(AC28+AA29)-AB29 -> 27 | AF29: 1 | AG29: =(AG28+AE29)-AF29 -> 9 | AK29: =(AK28+AI29)-AJ29 -> 26 | AO29: =(AO28+AM29)-AN29 -> 6
A30: 28 | E30: =(E29+C30)-D30 -> 100 | I30: =(I29+G30)-H30 -> 31 | M30: =(M29+K30)-L30 -> 0 | Q30: =(Q29+O30)-P30 -> 40 | U30: =(U29+S30)-T30 -> 48 | Y30: =(Y29+W30)-X30 -> 13 | AC30: =(AC29+AA30)-AB30 -> 27 | AG30: =(AG29+AE30)-AF30 -> 9 | AK30: =(AK29+AI30)-AJ30 -> 26 | AO30: =(AO29+AM30)-AN30 -> 6
A31: 29 | E31: =(E30+C31)-D31 -> 100 | I31: =(I30+G31)-H31 -> 31 | M31: =(M30+K31)-L31 -> 0 | Q31: =(Q30+O31)-P31 -> 40 | U31: =(U30+S31)-T31 -> 48 | Y31: =(Y30+W31)-X31 -> 13 | AC31: =(AC30+AA31)-AB31 -> 27 | AG31: =(AG30+AE31)-AF31 -> 9 | AK31: =(AK30+AI31)-AJ31 -> 26 | AO31: =(AO30+AM31)-AN31 -> 6
A32: 30 | E32: =(E31+C32)-D32 -> 100 | H32: 5 | I32: =(I31+G32)-H32 -> 26 | M32: =(M31+K32)-L32 -> 0 | P32: 4 | Q32: =(Q31+O32)-P32 -> 36 | U32: =(U31+S32)-T32 -> 48 | X32: 1 | Y32: =(Y31+W32)-X32 -> 12 | AC32: =(AC31+AA32)-AB32 -> 27 | AF32: 1 | AG32: =(AG31+AE32)-AF32 -> 8 | AJ32: 1 | AK32: =(AK31+AI32)-AJ32 -> 25 | AO32: =(AO31+AM32)-AN32 -> 6
A33: 31 | E33: =(E32+C33)-D33 -> 100 | I33: =(I32+G33)-H33 -> 26 | M33: =(M32+K33)-L33 -> 0 | Q33: =(Q32+O33)-P33 -> 36 | U33: =(U32+S33)-T33 -> 48 | Y33: =(Y32+W33)-X33 -> 12 | AC33: =(AC32+AA33)-AB33 -> 27 | AG33: =(AG32+AE33)-AF33 -> 8 | AK33: =(AK32+AI33)-AJ33 -> 25 | AO33: =(AO32+AM33)-AN33 -> 6
B34: TOTAL | C34: =SUM(C3:C33) -> 162 | D34: =SUM(D3:D33) -> 62 | E34: =E33 -> 100 | F34: TOTAL | G34: =SUM(G3:G33) -> 40 | H34: =SUM(H3:H33) -> 14 | I34: =I33 -> 26 | J34: TOTAL | K34: =SUM(K3:K30) -> 0 | L34: =SUM(L3:L31) -> 0 | M34: =M33 -> 0 | N34: TOTAL | O34: =SUM(O3:O30) -> 51 | P34: =SUM(P3:P31) -> 11 | Q34: =Q33 -> 36 | R34: TOTAL | S34: =SUM(S3:S30) -> 72 | T34: =SUM(T3:T31) -> 24 | U34: =U33 -> 48 | V34: TOTAL | W34: =SUM(W3:W30) -> 14 | X34: =SUM(X3:X31) -> 1 | Y34: =Y33 -> 12 | Z34: TOTAL | AA34: =SUM(AA3:AA30) -> 33 | AB34: =SUM(AB3:AB31) -> 6 | AC34: =AC33 -> 27 | AD34: TOTAL | AE34: =SUM(AE3:AE30) -> 16 | AF34: =SUM(AF3:AF31) -> 7 | AG34: =AG33 -> 8 | AH34: TOTAL | AI34: =SUM(AI3:AI30) -> 29 | AJ34: =SUM(AJ3:AJ31) -> 3 | AK34: =AK33 -> 25 | AL34: TOTAL | AM34: =SUM(AM3:AM30) -> 6 | AN34: =SUM(AN3:AN31) -> 0 | AO34: =AO33 -> 6

Sheet 01
C2: Litros | G2: Mini | K2: Molho | O2: Tetra Pak | S2: TP Culinário | W2: Coco Fresco 250g | AA2: Coco Fresco 500g | AE2: Coco Fresco 1kg | AI2: Coco Fresco Fino 500g | AM2: Coco Fresco Puro 1kg | AQ2: Coco Seco Fino 500g | AU2: Coco Seco Flocos 500g | AY2: Marshmallow 1Kg | BC2: Marshmallow 500g | BG2: Massa Folhada 1Kg | BK2: Massa Folhada 2,2Kg | BO2: Massa Semi-Folhada 2Kg
C3: Estoque Inicial | E3: 0 | G3: Estoque Inicial | I3: 0 | K3: Estoque Inicial | M3: 0 | O3: Estoque Inicial | Q3: 0 | S3: Estoque Inicial | U3: 0 | W3: Estoque Inicial | Y3: 0 | AA3: Estoque Inicial | AC3: 0 | AE3: Estoque Inicial | AG3: 0 | AI3: Estoque Inicial | AK3: 0 | AM3: Estoque Inicial | AO3: 0 | AQ3: Estoque Inicial | AS3: 0 | AU3: Estoque Inicial | AW3: 0 | AY3: Estoque Inicial | BA3: 0 | BC3: Estoque Inicial | BE3: 0 | BG3: Estoque Inicial | BI3: 0 | BK3: Estoque Inicial | BM3: 0 | BO3: Estoque Inicial | BQ3: 0
C4: Saída | E4: =-C31 -> 0 | G4: Saída | I4: =-G31 -> 0 | K4: Saída | M4: =-K31 -> 0 | O4: Saída | Q4: =-O31 -> 0 | S4: Saída | U4: =-S31 -> 0 | W4: Saída | Y4: =-W31 -> 0 | AA4: Saída | AC4: =-AA31 -> 0 | AE4: Saída | AG4: =-AE31 -> 0 | AI4: Saída | AK4: =-AI31 -> 0 | AM4: Saída | AO4: =-AM31 -> 0 | AQ4: Saída | AS4: =-AQ31 -> 0 | AU4: Saída | AW4: =-AU31 -> 0 | AY4: Saída | BA4: =-AY31 -> 0 | BC4: Saída | BE4: =-BC31 -> 0 | BG4: Saída | BI4: =-BG31 -> 0 | BK4: Saída | BM4: =-BK31 -> 0 | BO4: Saída | BQ4: =-BO31 -> 0
C5: Retorno | E5: =D31 -> 0 | G5: Retorno | I5: =H31 -> 0 | K5: Retorno | M5: =L31 -> 0 | O5: Retorno | Q5: =P31 -> 0 | S5: Retorno | U5: =T31 -> 0 | W5: Retorno | Y5: =X31 -> 0 | AA5: Retorno | AC5: =AB31 -> 0 | AE5: Retorno | AG5: =AF31 -> 0 | AI5: Retorno | AK5: =AJ31 -> 0 | AM5: Retorno | AO5: =AN31 -> 0 | AQ5: Retorno | AS5: =AR31 -> 0 | AU5: Retorno | AW5: =AV31 -> 0 | AY5: Retorno | BA5: =AZ31 -> 0 | BC5: Retorno | BE5: =BD31 -> 0 | BG5: Retorno | BI5: =BH31 -> 0 | BK5: Retorno | BM5: =BL31 -> 0 | BO5: Retorno | BQ5: =BP31 -> 0
C6: Trocas | E6: =-E31 -> 0 | G6: Trocas | I6: =-I31 -> 0 | K6: Trocas | M6: =-M31 -> 0 | O6: Trocas | Q6: =-Q31 -> 0 | S6: Trocas | U6: =-U31 -> 0 | W6: Trocas | Y6: =-Y31 -> 0 | AA6: Trocas | AC6: =-AC31 -> 0 | AE6: Trocas | AG6: =-AG31 -> 0 | AI6: Trocas | AK6: =-AK31 -> 0 | AM6: Trocas | AO6: =-AO31 -> 0 | AQ6: Trocas | AS6: =-AS31 -> 0 | AU6: Trocas | AW6: =-AW31 -> 0 | AY6: Trocas | BA6: =-BA31 -> 0 | BC6: Trocas | BE6: =-BE31 -> 0 | BG6: Trocas | BI6: =-BI31 -> 0 | BK6: Trocas | BM6: =-BM31 -> 0 | BO6: Trocas | BQ6: =-BQ31 -> 0
C7: Produção | G7: Produção | K7: Produção | O7: Compra / Entrega | S7: Compra / Entrega | W7: Compra / Entrega | AA7: Compra / Entrega | AE7: Compra / Entrega | AI7: Compra / Entrega | AM7: Compra / Entrega | AQ7: Compra / Entrega | AU7: Compra / Entrega | AY7: Compra / Entrega | BC7: Compra / Entrega | BG7: Compra / Entrega | BK7: Compra / Entrega | BO7: Compra / Entrega
C8: Estoque Atual | E8: =SUM(E3:E7) -> 0 | G8: Estoque Atual | I8: =SUM(I3:I7) -> 0 | K8: Estoque Atual | M8: =SUM(M3:M7) -> 0 | O8: Estoque Atual | Q8: =SUM(Q3:Q7) -> 0 | S8: Estoque Atual | U8: =SUM(U3:U7) -> 0 | W8: Estoque Atual | Y8: =SUM(Y3:Y7) -> 0 | AA8: Estoque Atual | AC8: =SUM(AC3:AC7) -> 0 | AE8: Estoque Atual | AG8: =SUM(AG3:AG7) -> 0 | AI8: Estoque Atual | AK8: =SUM(AK3:AK7) -> 0 | AM8: Estoque Atual | AO8: =SUM(AO3:AO7) -> 0 | AQ8: Estoque Atual | AS8: =SUM(AS3:AS7) -> 0 | AU8: Estoque Atual | AW8: =SUM(AW3:AW7) -> 0 | AY8: Estoque Atual | BA8: =SUM(BA3:BA7) -> 0 | BC8: Estoque Atual | BE8: =SUM(BE3:BE7) -> 0 | BG8: Estoque Atual | BI8: =SUM(BI3:BI7) -> 0 | BK8: Estoque Atual | BM8: =SUM(BM3:BM7) -> 0 | BO8: Estoque Atual | BQ8: =SUM(BQ3:BQ7) -> 0
B10: Vendedor | C10: Saída | D10: Retorno | E10: Trocas | F10: Vendas | G10: Saída | H10: Retorno | I10: Trocas | J10: Vendas | K10: Saída | L10: Retorno | M10: Trocas | N10: Vendas | O10: Saída | P10: Retorno | Q10: Trocas | R10: Vendas | S10: Saída | T10: Retorno | U10: Trocas | V10: Vendas | W10: Saída | X10: Retorno | Y10: Trocas | Z10: Vendas | AA10: Saída | AB10: Retorno | AC10: Trocas | AD10: Vendas | AE10: Saída | AF10: Retorno | AG10: Trocas | AH10: Vendas | AI10: Saída | AJ10: Retorno | AK10: Trocas | AL10: Vendas | AM10: Saída | AN10: Retorno | AO10: Trocas | AP10: Vendas | AQ10: Saída | AR10: Retorno | AS10: Trocas | AT10: Vendas | AU10: Saída | AV10: Retorno | AW10: Trocas | AX10: Vendas | AY10: Saída | AZ10: Retorno | BA10: Trocas | BB10: Vendas | BC10: Saída | BD10: Retorno | BE10: Trocas | BF10: Vendas | BG10: Saída | BH10: Retorno | BI10: Trocas | BJ10: Vendas | BK10: Saída | BL10: Retorno | BM10: Trocas | BN10: Vendas | BO10: Saída | BP10: Retorno | BQ10: Trocas | BR10: Vendas
F11: =C11-D11-E11 -> 0 | J11: =G11-H11-I11 -> 0 | N11: =K11-L11-M11 -> 0 | R11: =O11-P11-Q11 -> 0 | V11: =S11-T11-U11 -> 0 | Z11: =W11-X11-Y11 -> 0 | AD11: =AA11-AB11-AC11 -> 0 | AH11: =AE11-AF11-AG11 -> 0 | AL11: =AI11-AJ11-AK11 -> 0 | AP11: =AM11-AN11-AO11 -> 0 | AT11: =AQ11-AR11-AS11 -> 0 | AX11: =AU11-AV11-AW11 -> 0 | BB11: =AY11-AZ11-BA11 -> 0 | BF11: =BC11-BD11-BE11 -> 0 | BJ11: =BG11-BH11-BI11 -> 0 | BN11: =BK11-BL11-BM11 -> 0 | BR11: =BO11-BP11-BQ11 -> 0
F12: =C12-D12-E12 -> 0 | J12: =G12-H12-I12 -> 0 | N12: =K12-L12-M12 -> 0 | R12: =O12-P12-Q12 -> 0 | V12: =S12-T12-U12 -> 0 | Z12: =W12-X12-Y12 -> 0 | AD12: =AA12-AB12-AC12 -> 0 | AH12: =AE12-AF12-AG12 -> 0 | AL12: =AI12-AJ12-AK12 -> 0 | AP12: =AM12-AN12-AO12 -> 0 | AT12: =AQ12-AR12-AS12 -> 0 | AX12: =AU12-AV12-AW12 -> 0 | BB12: =AY12-AZ12-BA12 -> 0 | BF12: =BC12-BD12-BE12 -> 0 | BJ12: =BG12-BH12-BI12 -> 0 | BN12: =BK12-BL12-BM12 -> 0 | BR12: =BO12-BP12-BQ12 -> 0
F13: =C13-D13-E13 -> 0 | J13: =G13-H13-I13 -> 0 | N13: =K13-L13-M13 -> 0 | R13: =O13-P13-Q13 -> 0 | V13: =S13-T13-U13 -> 0 | Z13: =W13-X13-Y13 -> 0 | AD13: =AA13-AB13-AC13 -> 0 | AH13: =AE13-AF13-AG13 -> 0 | AL13: =AI13-AJ13-AK13 -> 0 | AP13: =AM13-AN13-AO13 -> 0 | AT13: =AQ13-AR13-AS13 -> 0 | AX13: =AU13-AV13-AW13 -> 0 | BB13: =AY13-AZ13-BA13 -> 0 | BF13: =BC13-BD13-BE13 -> 0 | BJ13: =BG13-BH13-BI13 -> 0 | BN13: =BK13-BL13-BM13 -> 0 | BR13: =BO13-BP13-BQ13 -> 0
F14: =C14-D14-E14 -> 0 | J14: =G14-H14-I14 -> 0 | N14: =K14-L14-M14 -> 0 | R14: =O14-P14-Q14 -> 0 | V14: =S14-T14-U14 -> 0 | Z14: =W14-X14-Y14 -> 0 | AD14: =AA14-AB14-AC14 -> 0 | AH14: =AE14-AF14-AG14 -> 0 | AL14: =AI14-AJ14-AK14 -> 0 | AP14: =AM14-AN14-AO14 -> 0 | AT14: =AQ14-AR14-AS14 -> 0 | AX14: =AU14-AV14-AW14 -> 0 | BB14: =AY14-AZ14-BA14 -> 0 | BF14: =BC14-BD14-BE14 -> 0 | BJ14: =BG14-BH14-BI14 -> 0 | BN14: =BK14-BL14-BM14 -> 0 | BR14: =BO14-BP14-BQ14 -> 0
F15: =C15-D15-E15 -> 0 | J15: =G15-H15-I15 -> 0 | N15: =K15-L15-M15 -> 0 | R15: =O15-P15-Q15 -> 0 | V15: =S15-T15-U15 -> 0 | Z15: =W15-X15-Y15 -> 0 | AD15: =AA15-AB15-AC15 -> 0 | AH15: =AE15-AF15-AG15 -> 0 | AL15: =AI15-AJ15-AK15 -> 0 | AP15: =AM15-AN15-AO15 -> 0 | AT15: =AQ15-AR15-AS15 -> 0 | AX15: =AU15-AV15-AW15 -> 0 | BB15: =AY15-AZ15-BA15 -> 0 | BF15: =BC15-BD15-BE15 -> 0 | BJ15: =BG15-BH15-BI15 -> 0 | BN15: =BK15-BL15-BM15 -> 0 | BR15: =BO15-BP15-BQ15 -> 0
F16: =C16-D16-E16 -> 0 | J16: =G16-H16-I16 -> 0 | N16: =K16-L16-M16 -> 0 | R16: =O16-P16-Q16 -> 0 | V16: =S16-T16-U16 -> 0 | Z16: =W16-X16-Y16 -> 0 | AD16: =AA16-AB16-AC16 -> 0 | AH16: =AE16-AF16-AG16 -> 0 | AL16: =AI16-AJ16-AK16 -> 0 | AP16: =AM16-AN16-AO16 -> 0 | AT16: =AQ16-AR16-AS16 -> 0 | AX16: =AU16-AV16-AW16 -> 0 | BB16: =AY16-AZ16-BA16 -> 0 | BF16: =BC16-BD16-BE16 -> 0 | BJ16: =BG16-BH16-BI16 -> 0 | BN16: =BK16-BL16-BM16 -> 0 | BR16: =BO16-BP16-BQ16 -> 0
F17: =C17-D17-E17 -> 0 | J17: =G17-H17-I17 -> 0 | N17: =K17-L17-M17 -> 0 | R17: =O17-P17-Q17 -> 0 | V17: =S17-T17-U17 -> 0 | Z17: =W17-X17-Y17 -> 0 | AD17: =AA17-AB17-AC17 -> 0 | AH17: =AE17-AF17-AG17 -> 0 | AL17: =AI17-AJ17-AK17 -> 0 | AP17: =AM17-AN17-AO17 -> 0 | AT17: =AQ17-AR17-AS17 -> 0 | AX17: =AU17-AV17-AW17 -> 0 | BB17: =AY17-AZ17-BA17 -> 0 | BF17: =BC17-BD17-BE17 -> 0 | BJ17: =BG17-BH17-BI17 -> 0 | BN17: =BK17-BL17-BM17 -> 0 | BR17: =BO17-BP17-BQ17 -> 0
F18: =C18-D18-E18 -> 0 | J18: =G18-H18-I18 -> 0 | N18: =K18-L18-M18 -> 0 | R18: =O18-P18-Q18 -> 0 | V18: =S18-T18-U18 -> 0 | Z18: =W18-X18-Y18 -> 0 | AD18: =AA18-AB18-AC18 -> 0 | AH18: =AE18-AF18-AG18 -> 0 | AL18: =AI18-AJ18-AK18 -> 0 | AP18: =AM18-AN18-AO18 -> 0 | AT18: =AQ18-AR18-AS18 -> 0 | AX18: =AU18-AV18-AW18 -> 0 | BB18: =AY18-AZ18-BA18 -> 0 | BF18: =BC18-BD18-BE18 -> 0 | BJ18: =BG18-BH18-BI18 -> 0 | BN18: =BK18-BL18-BM18 -> 0 | BR18: =BO18-BP18-BQ18 -> 0
F19: =C19-D19-E19 -> 0 | J19: =G19-H19-I19 -> 0 | N19: =K19-L19-M19 -> 0 | R19: =O19-P19-Q19 -> 0 | V19: =S19-T19-U19 -> 0 | Z19: =W19-X19-Y19 -> 0 | AD19: =AA19-AB19-AC19 -> 0 | AH19: =AE19-AF19-AG19 -> 0 | AL19: =AI19-AJ19-AK19 -> 0 | AP19: =AM19-AN19-AO19 -> 0 | AT19: =AQ19-AR19-AS19 -> 0 | AX19: =AU19-AV19-AW19 -> 0 | BB19: =AY19-AZ19-BA19 -> 0 | BF19: =BC19-BD19-BE19 -> 0 | BJ19: =BG19-BH19-BI19 -> 0 | BN19: =BK19-BL19-BM19 -> 0 | BR19: =BO19-BP19-BQ19 -> 0
F20: =C20-D20-E20 -> 0 | J20: =G20-H20-I20 -> 0 | N20: =K20-L20-M20 -> 0 | R20: =O20-P20-Q20 -> 0 | V20: =S20-T20-U20 -> 0 | Z20: =W20-X20-Y20 -> 0 | AD20: =AA20-AB20-AC20 -> 0 | AH20: =AE20-AF20-AG20 -> 0 | AL20: =AI20-AJ20-AK20 -> 0 | AP20: =AM20-AN20-AO20 -> 0 | AT20: =AQ20-AR20-AS20 -> 0 | AX20: =AU20-AV20-AW20 -> 0 | BB20: =AY20-AZ20-BA20 -> 0 | BF20: =BC20-BD20-BE20 -> 0 | BJ20: =BG20-BH20-BI20 -> 0 | BN20: =BK20-BL20-BM20 -> 0 | BR20: =BO20-BP20-BQ20 -> 0
F21: =C21-D21-E21 -> 0 | J21: =G21-H21-I21 -> 0 | N21: =K21-L21-M21 -> 0 | R21: =O21-P21-Q21 -> 0 | V21: =S21-T21-U21 -> 0 | Z21: =W21-X21-Y21 -> 0 | AD21: =AA21-AB21-AC21 -> 0 | AH21: =AE21-AF21-AG21 -> 0 | AL21: =AI21-AJ21-AK21 -> 0 | AP21: =AM21-AN21-AO21 -> 0 | AT21: =AQ21-AR21-AS21 -> 0 | AX21: =AU21-AV21-AW21 -> 0 | BB21: =AY21-AZ21-BA21 -> 0 | BF21: =BC21-BD21-BE21 -> 0 | BJ21: =BG21-BH21-BI21 -> 0 | BN21: =BK21-BL21-BM21 -> 0 | BR21: =BO21-BP21-BQ21 -> 0
F22: =C22-D22-E22 -> 0 | J22: =G22-H22-I22 -> 0 | N22: =K22-L22-M22 -> 0 | R22: =O22-P22-Q22 -> 0 | V22: =S22-T22-U22 -> 0 | Z22: =W22-X22-Y22 -> 0 | AD22: =AA22-AB22-AC22 -> 0 | AH22: =AE22-AF22-AG22 -> 0 | AL22: =AI22-AJ22-AK22 -> 0 | AP22: =AM22-AN22-AO22 -> 0 | AT22: =AQ22-AR22-AS22 -> 0 | AX22: =AU22-AV22-AW22 -> 0 | BB22: =AY22-AZ22-BA22 -> 0 | BF22: =BC22-BD22-BE22 -> 0 | BJ22: =BG22-BH22-BI22 -> 0 | BN22: =BK22-BL22-BM22 -> 0 | BR22: =BO22-BP22-BQ22 -> 0
... F30: =C30-D30-E30 -> 0 | J30: =G30-H30-I30 -> 0 | N30: =K30-L30-M30 -> 0 | R30: =O30-P30-Q30 -> 0 | V30: =S30-T30-U30 -> 0 | Z30: =W30-X30-Y30 -> 0 | AD30: =AA30-AB30-AC30 -> 0 | AH30: =AE30-AF30-AG30 -> 0 | AL30: =AI30-AJ30-AK30 -> 0 | AP30: =AM30-AN30-AO30 -> 0 | AT30: =AQ30-AR30-AS30 -> 0 | AX30: =AU30-AV30-AW30 -> 0 | BB30: =AY30-AZ30-BA30 -> 0 | BF30: =BC30-BD30-BE30 -> 0 | BJ30: =BG30-BH30-BI30 -> 0 | BN30: =BK30-BL30-BM30 -> 0 | BR30: =BO30-BP30-BQ30 -> 0
B31: TOTAL | C31: =SUM(C11:C30) -> 0 | D31: =SUM(D11:D30) -> 0 | E31: =SUM(E11:E30) -> 0 | F31: =SUM(F11:F30) -> 0 | G31: =SUM(G11:G30) -> 0 | H31: =SUM(H11:H30) -> 0 | I31: =SUM(I11:I30) -> 0 | J31: =SUM(J11:J30) -> 0 | ... BR31: =SUM(BR11:BR30) -> 0
C35: Ovo 1 L | G35: Gema 1 L | K35: Clara 1L | O35: Pão de Queijo 1 Kg | S35: Pão de Queijo 2 Kg | W35: PQ Requeijão | AA35: PQ Requeijão 4kg | AE35: PQ Frango | AI35: PQ Calabresa | AM35: PQ Goiabada | AQ35: PQ Doce de Leite | AU35: PQ Pizza | AY35: TP MM BRANCO | BC35: TP MM ROSA | BG35: TPC MM | BK35: DESMOLDANTE 1L | BO35: Melo Dito
C36: Estoque Inicial | E36: 0 | G36: Estoque Inicial | I36: 0 | K36: Estoque Inicial | M36: 0 | O36: Estoque Inicial | Q36: 0 | S36: Estoque Inicial | U36: 0 | W36: Estoque Inicial | Y36: 0 | AA36: Estoque Inicial | AC36: 0 | AE36: Estoque Inicial | AG36: 0 | AI36: Estoque Inicial | AK36: 0 | AM36: Estoque Inicial | AO36: 0 | AQ36: Estoque Inicial | AS36: 0 | AU36: Estoque Inicial | AW36: 0 | AY36: Estoque Inicial | BA36: 0 | BC36: Estoque Inicial | BE36: 0 | BG36: Estoque Inicial | BI36: 0 | BK36: Estoque Inicial | BM36: 0 | BO36: Estoque Inicial | BQ36: 0
C37: Saída | E37: =-C64 -> 0 | G37: Saída | I37: =-G64 -> 0 | K37: Saída | M37: =-K64 -> 0 | O37: Saída | Q37: =-O64 -> 0 | S37: Saída | U37: =-S64 -> 0 | W37: Saída | Y37: =-W64 -> 0 | AA37: Saída | AC37: =-AA64 -> 0 | AE37: Saída | AG37: =-AE64 -> 0 | AI37: Saída | AK37: =-AI64 -> 0 | AM37: Saída | AO37: =-AM64 -> 0 | AQ37: Saída | AS37: =-AQ64 -> 0 | AU37: Saída | AW37: =-AU64 -> 0 | AY37: Saída | BA37: =-AY64 -> 0 | BC37: Saída | BE37: =-BC64 -> 0 | BG37: Saída | BI37: =-BG64 -> 0 | BK37: Saída | BM37: =-BK64 -> 0 | BO37: Saída | BQ37: =-BO64 -> 0
C38: Retorno | E38: =D64 -> 0 | G38: Retorno | I38: =H64 -> 0 | K38: Retorno | M38: =L64 -> 0 | O38: Retorno | Q38: =P64 -> 0 | S38: Retorno | U38: =T64 -> 0 | W38: Retorno | Y38: =X64 -> 0 | AA38: Retorno | AC38: =AB64 -> 0 | AE38: Retorno | AG38: =AF64 -> 0 | AI38: Retorno | AK38: =AJ64 -> 0 | AM38: Retorno | AO38: =AN64 -> 0 | AQ38: Retorno | AS38: =AR64 -> 0 | AU38: Retorno | AW38: =AV64 -> 0 | AY38: Retorno | BA38: =AZ64 -> 0 | BC38: Retorno | BE38: =BD64 -> 0 | BG38: Retorno | BI38: =BH64 -> 0 | BK38: Retorno | BM38: =BL64 -> 0 | BO38: Retorno | BQ38: =BP64 -> 0
C39: Trocas | E39: =-E64 -> 0 | G39: Trocas | I39: =-I64 -> 0 | K39: Trocas | M39: =-M64 -> 0 | O39: Trocas | Q39: =-Q64 -> 0 | S39: Trocas | U39: =-U64 -> 0 | W39: Trocas | Y39: =-Y64 -> 0 | AA39: Trocas | AC39: =-AC64 -> 0 | AE39: Trocas | AG39: =-AG64 -> 0 | AI39: Trocas | AK39: =-AK64 -> 0 | AM39: Trocas | AO39: =-AO64 -> 0 | AQ39: Trocas | AS39: =-AS64 -> 0 | AU39: Trocas | AW39: =-AW64 -> 0 | AY39: Trocas | BA39: =-BA64 -> 0 | BC39: Trocas | BE39: =-BE64 -> 0 | BG39: Trocas | BI39: =-BI64 -> 0 | BK39: Trocas | BM39: =-BM64 -> 0 | BO39: Trocas | BQ39: =-BQ64 -> 0
C40: Compra / Entrega | G40: Compra / Entrega | K40: Compra / Entrega | O40: Compra / Entrega | S40: Compra / Entrega | W40: Compra / Entrega | AA40: Compra / Entrega | AE40: Compra / Entrega | AI40: Compra / Entrega | AM40: Compra / Entrega | AQ40: Compra / Entrega | AU40: Compra / Entrega | AY40: Compra / Entrega | BC40: Compra / Entrega | BG40: Compra / Entrega | BK40: Compra / Entrega | BO40: Compra / Entrega
C41: Estoque Atual | E41: =SUM(E36:E40) -> 0 | G41: Estoque Atual | I41: =SUM(I36:I40) -> 0 | K41: Estoque Atual | M41: =SUM(M36:M40) -> 0 | O41: Estoque Atual | Q41: =SUM(Q36:Q40) -> 0 | S41: Estoque Atual | U41: =SUM(U36:U40) -> 0 | W41: Estoque Atual | Y41: =SUM(Y36:Y40) -> 0 | AA41: Estoque Atual | AC41: =SUM(AC36:AC40) -> 0 | AE41: Estoque Atual | AG41: =SUM(AG36:AG40) -> 0 | AI41: Estoque Atual | AK41: =SUM(AK36:AK40) -> 0 | AM41: Estoque Atual | AO41: =SUM(AO36:AO40) -> 0 | AQ41: Estoque Atual | AS41: =SUM(AS36:AS40) -> 0 | AU41: Estoque Atual | AW41: =SUM(AW36:AW40) -> 0 | AY41: Estoque Atual | BA41: =SUM(BA36:BA40) -> 0 | BC41: Estoque Atual | BE41: =SUM(BE36:BE40) -> 0 | BG41: Estoque Atual | BI41: =SUM(BI36:BI40) -> 0 | BK41: Estoque Atual | BM41: =SUM(BM36:BM40) -> 0 | BO41: Estoque Atual | BQ41: =SUM(BQ36:BQ40) -> 0
B43: Vendedor | C43: Saída | D43: Retorno | E43: Trocas | F43: Vendas | G43: Saída | H43: Retorno | I43: Trocas | J43: Vendas | K43: Saída | L43: Retorno | M43: Trocas | N43: Vendas | O43: Saída | P43: Retorno | Q43: Trocas | R43: Vendas | S43: Saída | T43: Retorno | U43: Trocas | V43: Vendas | W43: Saída | X43: Retorno | Y43: Trocas | Z43: Vendas | AA43: Saída | AB43: Retorno | AC43: Trocas | AD43: Vendas | AE43: Saída | AF43: Retorno | AG43: Trocas | AH43: Vendas | AI43: Saída | AJ43: Retorno | AK43: Trocas | AL43: Vendas | AM43: Saída | AN43: Retorno | AO43: Trocas | AP43: Vendas | AQ43: Saída | AR43: Retorno | AS43: Trocas | AT43: Vendas | AU43: Saída | AV43: Retorno | AW43: Trocas | AX43: Vendas | AY43: Saída | AZ43: Retorno | BA43: Trocas | BB43: Vendas | BC43: Saída | BD43: Retorno | BE43: Trocas | BF43: Vendas | BG43: Saída | BH43: Retorno | BI43: Trocas | BJ43: Vendas | BK43: Saída | BL43: Retorno | BM43: Trocas | BN43: Vendas | BO43: Saída | BP43: Retorno | BQ43: Trocas | BR43: Vendas
B44: =B11 -> 0 | F44: =C44-D44-E44 -> 0 | J44: =G44-H44-I44 -> 0 | N44: =K44-L44-M44 -> 0 | R44: =O44-P44-Q44 -> 0 | V44: =S44-T44-U44 -> 0 | Z44: =W44-X44-Y44 -> 0 | AD44: =AA44-AB44-AC44 -> 0 | AH44: =AE44-AF44-AG44 -> 0 | AL44: =AI44-AJ44-AK44 -> 0 | AP44: =AM44-AN44-AO44 -> 0 | AT44: =AQ44-AR44-AS44 -> 0 | AX44: =AU44-AV44-AW44 -> 0 | BB44: =AY44-AZ44-BA44 -> 0 | BF44: =BC44-BD44-BE44 -> 0 | BJ44: =BG44-BH44-BI44 -> 0 | BN44: =BK44-BL44-BM44 -> 0 | BR44: =BO44-BP44-BQ44 -> 0
B45: =B12 -> 0 | F45: =C45-D45-E45 -> 0 | J45: =G45-H45-I45 -> 0 | N45: =K45-L45-M45 -> 0 | R45: =O45-P45-Q45 -> 0 | V45: =S45-T45-U45 -> 0 | Z45: =W45-X45-Y45 -> 0 | AD45: =AA45-AB45-AC45 -> 0 | AH45: =AE45-AF45-AG45 -> 0 | AL45: =AI45-AJ45-AK45 -> 0 | AP45: =AM45-AN45-AO45 -> 0 | AT45: =AQ45-AR45-AS45 -> 0 | AX45: =AU45-AV45-AW45 -> 0 | BB45: =AY45-AZ45-BA45 -> 0 | BF45: =BC45-BD45-BE45 -> 0 | BJ45: =BG45-BH45-BI45 -> 0 | BN45: =BK45-BL45-BM45 -> 0 | BR45: =BO45-BP45-BQ45 -> 0
B46: =B13 -> 0 | F46: =C46-D46-E46 -> 0 | J46: =G46-H46-I46 -> 0 | N46: =K46-L46-M46 -> 0 | R46: =O46-P46-Q46 -> 0 | V46: =S46-T46-U46 -> 0 | Z46: =W46-X46-Y46 -> 0 | AD46: =AA46-AB46-AC46 -> 0 | AH46: =AE46-AF46-AG46 -> 0 | AL46: =AI46-AJ46-AK46 -> 0 | AP46: =AM46-AN46-AO46 -> 0 | AT46: =AQ46-AR46-AS46 -> 0 | AX46: =AU46-AV46-AW46 -> 0 | BB46: =AY46-AZ46-BA46 -> 0 | BF46: =BC46-BD46-BE46 -> 0 | BJ46: =BG46-BH46-BI46 -> 0 | BN46: =BK46-BL46-BM46 -> 0 | BR46: =BO46-BP46-BQ46 -> 0
B47: =B14 -> 0 | F47: =C47-D47-E47 -> 0 | J47: =G47-H47-I47 -> 0 | N47: =K47-L47-M47 -> 0 | R47: =O47-P47-Q47 -> 0 | V47: =S47-T47-U47 -> 0 | Z47: =W47-X47-Y47 -> 0 | AD47: =AA47-AB47-AC47 -> 0 | AH47: =AE47-AF47-AG47 -> 0 | AL47: =AI47-AJ47-AK47 -> 0 | AP47: =AM47-AN47-AO47 -> 0 | AT47: =AQ47-AR47-AS47 -> 0 | AX47: =AU47-AV47-AW47 -> 0 | BB47: =AY47-AZ47-BA47 -> 0 | BF47: =BC47-BD47-BE47 -> 0 | BJ47: =BG47-BH47-BI47 -> 0 | BN47: =BK47-BL47-BM47 -> 0 | BR47: =BO47-BP47-BQ47 -> 0
B48: =B15 -> 0 | F48: =C48-D48-E48 -> 0 | J48: =G48-H48-I48 -> 0 | N48: =K48-L48-M48 -> 0 | R48: =O48-P48-Q48 -> 0 | V48: =S48-T48-U48 -> 0 | Z48: =W48-X48-Y48 -> 0 | AD48: =AA48-AB48-AC48 -> 0 | AH48: =AE48-AF48-AG48 -> 0 | AL48: =AI48-AJ48-AK48 -> 0 | AP48: =AM48-AN48-AO48 -> 0 | AT48: =AQ48-AR48-AS48 -> 0 | AX48: =AU48-AV48-AW48 -> 0 | BB48: =AY48-AZ48-BA48 -> 0 | BF48: =BC48-BD48-BE48 -> 0 | BJ48: =BG48-BH48-BI48 -> 0 | BN48: =BK48-BL48-BM48 -> 0 | BR48: =BO48-BP48-BQ48 -> 0
B49: =B16 -> 0 | F49: =C49-D49-E49 -> 0 | J49: =G49-H49-I49 -> 0 | N49: =K49-L49-M49 -> 0 | R49: =O49-P49-Q49 -> 0 | V49: =S49-T49-U49 -> 0 | Z49: =W49-X49-Y49 -> 0 | AD49: =AA49-AB49-AC49 -> 0 | AH49: =AE49-AF49-AG49 -> 0 | AL49: =AI49-AJ49-AK49 -> 0 | AP49: =AM49-AN49-AO49 -> 0 | AT49: =AQ49-AR49-AS49 -> 0 | AX49: =AU49-AV49-AW49 -> 0 | BB49: =AY49-AZ49-BA49 -> 0 | BF49: =BC49-BD49-BE49 -> 0 | BJ49: =BG49-BH49-BI49 -> 0 | BN49: =BK49-BL49-BM49 -> 0 | BR49: =BO49-BP49-BQ49 -> 0
B50: =B17 -> 0 | F50: =C50-D50-E50 -> 0 | J50: =G50-H50-I50 -> 0 | N50: =K50-L50-M50 -> 0 | R50: =O50-P50-Q50 -> 0 | V50: =S50-T50-U50 -> 0 | Z50: =W50-X50-Y50 -> 0 | AD50: =AA50-AB50-AC50 -> 0 | AH50: =AE50-AF50-AG50 -> 0 | AL50: =AI50-AJ50-AK50 -> 0 | AP50: =AM50-AN50-AO50 -> 0 | AT50: =AQ50-AR50-AS50 -> 0 | AX50: =AU50-AV50-AW50 -> 0 | BB50: =AY50-AZ50-BA50 -> 0 | BF50: =BC50-BD50-BE50 -> 0 | BJ50: =BG50-BH50-BI50 -> 0 | BN50: =BK50-BL50-BM50 -> 0 | BR50: =BO50-BP50-BQ50 -> 0
B51: =B18 -> 0 | F51: =C51-D51-E51 -> 0 | J51: =G51-H51-I51 -> 0 | N51: =K51-L51-M51 -> 0 | R51: =O51-P51-Q51 -> 0 | V51: =S51-T51-U51 -> 0 | Z51: =W51-X51-Y51 -> 0 | AD51: =AA51-AB51-AC51 -> 0 | AH51: =AE51-AF51-AG51 -> 0 | AL51: =AI51-AJ51-AK51 -> 0 | AP51: =AM51-AN51-AO51 -> 0 | AT51: =AQ51-AR51-AS51 -> 0 | AX51: =AU51-AV51-AW51 -> 0 | BB51: =AY51-AZ51-BA51 -> 0 | BF51: =BC51-BD51-BE51 -> 0 | BJ51: =BG51-BH51-BI51 -> 0 | BN51: =BK51-BL51-BM51 -> 0 | BR51: =BO51-BP51-BQ51 -> 0
B52: =B19 -> 0 | F52: =C52-D52-E52 -> 0 | J52: =G52-H52-I52 -> 0 | N52: =K52-L52-M52 -> 0 | R52: =O52-P52-Q52 -> 0 | V52: =S52-T52-U52 -> 0 | Z52: =W52-X52-Y52 -> 0 | AD52: =AA52-AB52-AC52 -> 0 | AH52: =AE52-AF52-AG52 -> 0 | AL52: =AI52-AJ52-AK52 -> 0 | AP52: =AM52-AN52-AO52 -> 0 | AT52: =AQ52-AR52-AS52 -> 0 | AX52: =AU52-AV52-AW52 -> 0 | BB52: =AY52-AZ52-BA52 -> 0 | BF52: =BC52-BD52-BE52 -> 0 | BJ52: =BG52-BH52-BI52 -> 0 | BN52: =BK52-BL52-BM52 -> 0 | BR52: =BO52-BP52-BQ52 -> 0
B53: =B20 -> 0 | F53: =C53-D53-E53 -> 0 | J53: =G53-H53-I53 -> 0 | N53: =K53-L53-M53 -> 0 | R53: =O53-P53-Q53 -> 0 | V53: =S53-T53-U53 -> 0 | Z53: =W53-X53-Y53 -> 0 | AD53: =AA53-AB53-AC53 -> 0 | AH53: =AE53-AF53-AG53 -> 0 | AL53: =AI53-AJ53-AK53 -> 0 | AP53: =AM53-AN53-AO53 -> 0 | AT53: =AQ53-AR53-AS53 -> 0 | AX53: =AU53-AV53-AW53 -> 0 | BB53: =AY53-AZ53-BA53 -> 0 | BF53: =BC53-BD53-BE53 -> 0 | BJ53: =BG53-BH53-BI53 -> 0 | BN53: =BK53-BL53-BM53 -> 0 | BR53: =BO53-BP53-BQ53 -> 0
...

Sheet 02
C2: ='01'!C2:F2 -> Litros | G2: ='01'!G2:J2 -> Mini | K2: ='01'!K2:N2 -> Molho | O2: ='01'!O2:R2 -> Tetra Pak | S2: ='01'!S2:V2 -> TP Culinário | W2: ='01'!W2:Z2 -> Coco Fresco 250g | AA2: ='01'!AA2:AD2 -> Coco Fresco 500g | AE2: ='01'!AE2:AH2 -> Coco Fresco 1kg | AI2: ='01'!AI2:AL2 -> Coco Fresco Fino 500g | AM2: ='01'!AM2:AP2 -> Coco Fresco Puro 1kg | AQ2: ='01'!AQ2:AT2 -> Coco Seco Fino 500g | AU2: ='01'!AU2:AX2 -> Coco Seco Flocos 500g | AY2: ='01'!AY2:BB2 -> Marshmallow 1Kg | BC2: ='01'!BC2:BF2 -> Marshmallow 500g | BG2: ='01'!BG2:BJ2 -> Massa Folhada 1Kg | BK2: ='01'!BK2:BN2 -> Massa Folhada 2,2Kg | BO2: ='01'!BO2:BR2 -> Massa Semi-Folhada 2Kg
C3: Estoque Inicial | E3: ='01'!E8:F8 -> 0 | G3: Estoque Inicial | I3: ='01'!I8:J8 -> 0 | K3: Estoque Inicial | M3: ='01'!M8:N8 -> 0 | O3: Estoque Inicial | Q3: ='01'!Q8:R8 -> 0 | S3: Estoque Inicial | U3: ='01'!U8:V8 -> 0 | W3: Estoque Inicial | Y3: ='01'!Y8:Z8 -> 0 | AA3: Estoque Inicial | AC3: ='01'!AC8:AD8 -> 0 | AE3: Estoque Inicial | AG3: ='01'!AG8:AH8 -> 0 | AI3: Estoque Inicial | AK3: ='01'!AK8:AL8 -> 0 | AM3: Estoque Inicial | AO3: ='01'!AO8:AP8 -> 0 | AQ3: Estoque Inicial | AS3: ='01'!AS8:AT8 -> 0 | AU3: Estoque Inicial | AW3: ='01'!AW8:AX8 -> 0 | AY3: Estoque Inicial | BA3: ='01'!BA8:BB8 -> 0 | BC3: Estoque Inicial | BE3: ='01'!BE8:BF8 -> 0 | BG3: Estoque Inicial | BI3: ='01'!BI8:BJ8 -> 0 | BK3: Estoque Inicial | BM3: ='01'!BM8:BN8 -> 0 | BO3: Estoque Inicial | BQ3: ='01'!BQ8:BR8 -> 0
C4: Saída | E4: =-C31 -> 0 | G4: Saída | I4: =-G31 -> 0 | K4: Saída | M4: =-K31 -> 0 | O4: Saída | Q4: =-O31 -> 0 | S4: Saída | U4: =-S31 -> 0 | W4: Saída | Y4: =-W31 -> 0 | AA4: Saída | AC4: =-AA31 -> 0 | AE4: Saída | AG4: =-AE31 -> 0 | AI4: Saída | AK4: =-AI31 -> 0 | AM4: Saída | AO4: =-AM31 -> 0 | AQ4: Saída | AS4: =-AQ31 -> 0 | AU4: Saída | AW4: =-AU31 -> 0 | AY4: Saída | BA4: =-AY31 -> 0 | BC4: Saída | BE4: =-BC31 -> 0 | BG4: Saída | BI4: =-BG31 -> 0 | BK4: Saída | BM4: =-BK31 -> 0 | BO4: Saída | BQ4: =-BO31 -> 0
C5: Retorno | E5: =D31 -> 0 | G5: Retorno | I5: =H31 -> 0 | K5: Retorno | M5: =L31 -> 0 | O5: Retorno | Q5: =P31 -> 0 | S5: Retorno | U5: =T31 -> 0 | W5: Retorno | Y5: =X31 -> 0 | AA5: Retorno | AC5: =AB31 -> 0 | AE5: Retorno | AG5: =AF31 -> 0 | AI5: Retorno | AK5: =AJ31 -> 0 | AM5: Retorno | AO5: =AN31 -> 0 | AQ5: Retorno | AS5: =AR31 -> 0 | AU5: Retorno | AW5: =AV31 -> 0 | AY5: Retorno | BA5: =AZ31 -> 0 | BC5: Retorno | BE5: =BD31 -> 0 | BG5: Retorno | BI5: =BH31 -> 0 | BK5: Retorno | BM5: =BL31 -> 0 | BO5: Retorno | BQ5: =BP31 -> 0
C6: Trocas | E6: =-E31 -> 0 | G6: Trocas | I6: =-I31 -> 0 | K6: Trocas | M6: =-M31 -> 0 | O6: Trocas | Q6: =-Q31 -> 0 | S6: Trocas | U6: =-U31 -> 0 | W6: Trocas | Y6: =-Y31 -> 0 | AA6: Trocas | AC6: =-AC31 -> 0 | AE6: Trocas | AG6: =-AG31 -> 0 | AI6: Trocas | AK6: =-AK31 -> 0 | AM6: Trocas | AO6: =-AO31 -> 0 | AQ6: Trocas | AS6: =-AS31 -> 0 | AU6: Trocas | AW6: =-AW31 -> 0 | AY6: Trocas | BA6: =-BA31 -> 0 | BC6: Trocas | BE6: =-BE31 -> 0 | BG6: Trocas | BI6: =-BI31 -> 0 | BK6: Trocas | BM6: =-BM31 -> 0 | BO6: Trocas | BQ6: =-BQ31 -> 0
C7: Produção | G7: Produção | K7: Produção | O7: Compra / Entrega | S7: Compra / Entrega | W7: Compra / Entrega | AA7: Compra / Entrega | AE7: Compra / Entrega | AI7: Compra / Entrega | AM7: Compra / Entrega | AQ7: Compra / Entrega | AU7: Compra / Entrega | AY7: Compra / Entrega | BC7: Compra / Entrega | BG7: Compra / Entrega | BK7: Compra / Entrega | BO7: Compra / Entrega
C8: Estoque Atual | E8: =SUM(E3:E7) -> 0 | G8: Estoque Atual | I8: =SUM(I3:I7) -> 0 | K8: Estoque Atual | M8: =SUM(M3:M7) -> 0 | O8: Estoque Atual | Q8: =SUM(Q3:Q7) -> 0 | S8: Estoque Atual | U8: =SUM(U3:U7) -> 0 | W8: Estoque Atual | Y8: =SUM(Y3:Y7) -> 0 | AA8: Estoque Atual | AC8: =SUM(AC3:AC7) -> 0 | AE8: Estoque Atual | AG8: =SUM(AG3:AG7) -> 0 | AI8: Estoque Atual | AK8: =SUM(AK3:AK7) -> 0 | AM8: Estoque Atual | AO8: =SUM(AO3:AO7) -> 0 | AQ8: Estoque Atual | AS8: =SUM(AS3:AS7) -> 0 | AU8: Estoque Atual | AW8: =SUM(AW3:AW7) -> 0 | AY8: Estoque Atual | BA8: =SUM(BA3:BA7) -> 0 | BC8: Estoque Atual | BE8: =SUM(BE3:BE7) -> 0 | BG8: Estoque Atual | BI8: =SUM(BI3:BI7) -> 0 | BK8: Estoque Atual | BM8: =SUM(BM3:BM7) -> 0 | BO8: Estoque Atual | BQ8: =SUM(BQ3:BQ7) -> 0
B10: Vendedor | C10: Saída | D10: Retorno | E10: Trocas | F10: Vendas | G10: Saída | H10: Retorno | I10: Trocas | J10: Vendas | K10: Saída | L10: Retorno | M10: Trocas | N10: Vendas | O10: Saída | P10: Retorno | Q10: Trocas | R10: Vendas | S10: Saída | T10: Retorno | U10: Trocas | V10: Vendas | W10: Saída | X10: Retorno | Y10: Trocas | Z10: Vendas | AA10: Saída | AB10: Retorno | AC10: Trocas | AD10: Vendas | AE10: Saída | AF10: Retorno | AG10: Trocas | AH10: Vendas | AI10: Saída | AJ10: Retorno | AK10: Trocas | AL10: Vendas | AM10: Saída | AN10: Retorno | AO10: Trocas | AP10: Vendas | AQ10: Saída | AR10: Retorno | AS10: Trocas | AT10: Vendas | AU10: Saída | AV10: Retorno | AW10: Trocas | AX10: Vendas | AY10: Saída | AZ10: Retorno | BA10: Trocas | BB10: Vendas | BC10: Saída | BD10: Retorno | BE10: Trocas | BF10: Vendas | BG10: Saída | BH10: Retorno | BI10: Trocas | BJ10: Vendas | BK10: Saída | BL10: Retorno | BM10: Trocas | BN10: Vendas | BO10: Saída | BP10: Retorno | BQ10: Trocas | BR10: Vendas
F11: =C11-D11-E11 -> 0 | J11: =G11-H11-I11 -> 0 | N11: =K11-L11-M11 -> 0 | R11: =O11-P11-Q11 -> 0 | V11: =S11-T11-U11 -> 0 | Z11: =W11-X11-Y11 -> 0 | AD11: =AA11-AB11-AC11 -> 0 | AH11: =AE11-AF11-AG11 -> 0 | AL11: =AI11-AJ11-AK11 -> 0 | AP11: =AM11-AN11-AO11 -> 0 | AT11: =AQ11-AR11-AS11 -> 0 | AX11: =AU11-AV11-AW11 -> 0 | BB11: =AY11-AZ11-BA11 -> 0 | BF11: =BC11-BD11-BE11 -> 0 | BJ11: =BG11-BH11-BI11 -> 0 | BN11: =BK11-BL11-BM11 -> 0 | BR11: =BO11-BP11-BQ11 -> 0
F12: =C12-D12-E12 -> 0 | J12: =G12-H12-I12 -> 0 | N12: =K12-L12-M12 -> 0 | R12: =O12-P12-Q12 -> 0 | V12: =S12-T12-U12 -> 0 | Z12: =W12-X12-Y12 -> 0 | AD12: =AA12-AB12-AC12 -> 0 | AH12: =AE12-AF12-AG12 -> 0 | AL12: =AI12-AJ12-AK12 -> 0 | AP12: =AM12-AN12-AO12 -> 0 | AT12: =AQ12-AR12-AS12 -> 0 | AX12: =AU12-AV12-AW12 -> 0 | BB12: =AY12-AZ12-BA12 -> 0 | BF12: =BC12-BD12-BE12 -> 0 | BJ12: =BG12-BH12-BI12 -> 0 | BN12: =BK12-BL12-BM12 -> 0 | BR12: =BO12-BP12-BQ12 -> 0
F13: =C13-D13-E13 -> 0 | J13: =G13-H13-I13 -> 0 | N13: =K13-L13-M13 -> 0 | R13: =O13-P13-Q13 -> 0 | V13: =S13-T13-U13 -> 0 | Z13: =W13-X13-Y13 -> 0 | AD13: =AA13-AB13-AC13 -> 0 | AH13: =AE13-AF13-AG13 -> 0 | AL13: =AI13-AJ13-AK13 -> 0 | AP13: =AM13-AN13-AO13 -> 0 | AT13: =AQ13-AR13-AS13 -> 0 | AX13: =AU13-AV13-AW13 -> 0 | BB13: =AY13-AZ13-BA13 -> 0 | BF13: =BC13-BD13-BE13 -> 0 | BJ13: =BG13-BH13-BI13 -> 0 | BN13: =BK13-BL13-BM13 -> 0 | BR13: =BO13-BP13-BQ13 -> 0
F14: =C14-D14-E14 -> 0 | J14: =G14-H14-I14 -> 0 | N14: =K14-L14-M14 -> 0 | R14: =O14-P14-Q14 -> 0 | V14: =S14-T14-U14 -> 0 | Z14: =W14-X14-Y14 -> 0 | AD14: =AA14-AB14-AC14 -> 0 | AH14: =AE14-AF14-AG14 -> 0 | AL14: =AI14-AJ14-AK14 -> 0 | AP14: =AM14-AN14-AO14 -> 0 | AT14: =AQ14-AR14-AS14 -> 0 | AX14: =AU14-AV14-AW14 -> 0 | BB14: =AY14-AZ14-BA14 -> 0 | BF14: =BC14-BD14-BE14 -> 0 | BJ14: =BG14-BH14-BI14 -> 0 | BN14: =BK14-BL14-BM14 -> 0 | BR14: =BO14-BP14-BQ14 -> 0
F15: =C15-D15-E15 -> 0 | J15: =G15-H15-I15 -> 0 | N15: =K15-L15-M15 -> 0 | R15: =O15-P15-Q15 -> 0 | V15: =S15-T15-U15 -> 0 | Z15: =W15-X15-Y15 -> 0 | AD15: =AA15-AB15-AC15 -> 0 | AH15: =AE15-AF15-AG15 -> 0 | AL15: =AI15-AJ15-AK15 -> 0 | AP15: =AM15-AN15-AO15 -> 0 | AT15: =AQ15-AR15-AS15 -> 0 | AX15: =AU15-AV15-AW15 -> 0 | BB15: =AY15-AZ15-BA15 -> 0 | BF15: =BC15-BD15-BE15 -> 0 | BJ15: =BG15-BH15-BI15 -> 0 | BN15: =BK15-BL15-BM15 -> 0 | BR15: =BO15-BP15-BQ15 -> 0
F16: =C16-D16-E16 -> 0 | J16: =G16-H16-I16 -> 0 | N16: =K16-L16-M16 -> 0 | R16: =O16-P16-Q16 -> 0 | V16: =S16-T16-U16 -> 0 | Z16: =W16-X16-Y16 -> 0 | AD16: =AA16-AB16-AC16 -> 0 | AH16: =AE16-AF16-AG16 -> 0 | AL16: =AI16-AJ16-AK16 -> 0 | AP16: =AM16-AN16-AO16 -> 0 | AT16: =AQ16-AR16-AS16 -> 0 | AX16: =AU16-AV16-AW16 -> 0 | BB16: =AY16-AZ16-BA16 -> 0 | BF16: =BC16-BD16-BE16 -> 0 | BJ16: =BG16-BH16-BI16 -> 0 | BN16: =BK16-BL16-BM16 -> 0 | BR16: =BO16-BP16-BQ16 -> 0
F17: =C17-D17-E17 -> 0 | J17: =G17-H17-I17 -> 0 | N17: =K17-L17-M17 -> 0 | R17: =O17-P17-Q17 -> 0 | V17: =S17-T17-U17 -> 0 | Z17: =W17-X17-Y17 -> 0 | AD17: =AA17-AB17-AC17 -> 0 | AH17: =AE17-AF17-AG17 -> 0 | AL17: =AI17-AJ17-AK17 -> 0 | AP17: =AM17-AN17-AO17 -> 0 | AT17: =AQ17-AR17-AS17 -> 0 | AX17: =AU17-AV17-AW17 -> 0 | BB17: =AY17-AZ17-BA17 -> 0 | BF17: =BC17-BD17-BE17 -> 0 | BJ17: =BG17-BH17-BI17 -> 0 | BN17: =BK17-BL17-BM17 -> 0 | BR17: =BO17-BP17-BQ17 -> 0
F18: =C18-D18-E18 -> 0 | J18: =G18-H18-I18 -> 0 | N18: =K18-L18-M18 -> 0 | R18: =O18-P18-Q18 -> 0 | V18: =S18-T18-U18 -> 0 | Z18: =W18-X18-Y18 -> 0 | AD18: =AA18-AB18-AC18 -> 0 | AH18: =AE18-AF18-AG18 -> 0 | AL18: =AI18-AJ18-AK18 -> 0 | AP18: =AM18-AN18-AO18 -> 0 | AT18: =AQ18-AR18-AS18 -> 0 | AX18: =AU18-AV18-AW18 -> 0 | BB18: =AY18-AZ18-BA18 -> 0 | BF18: =BC18-BD18-BE18 -> 0 | BJ18: =BG18-BH18-BI18 -> 0 | BN18: =BK18-BL18-BM18 -> 0 | BR18: =BO18-BP18-BQ18 -> 0
F19: =C19-D19-E19 -> 0 | J19: =G19-H19-I19 -> 0 | N19: =K19-L19-M19 -> 0 | R19: =O19-P19-Q19 -> 0 | V19: =S19-T19-U19 -> 0 | Z19: =W19-X19-Y19 -> 0 | AD19: =AA19-AB19-AC19 -> 0 | AH19: =AE19-AF19-AG19 -> 0 | AL19: =AI19-AJ19-AK19 -> 0 | AP19: =AM19-AN19-AO19 -> 0 | AT19: =AQ19-AR19-AS19 -> 0 | AX19: =AU19-AV19-AW19 -> 0 | BB19: =AY19-AZ19-BA19 -> 0 | BF19: =BC19-BD19-BE19 -> 0 | BJ19: =BG19-BH19-BI19 -> 0 | BN19: =BK19-BL19-BM19 -> 0 | BR19: =BO19-BP19-BQ19 -> 0
F20: =C20-D20-E20 -> 0 | J20: =G20-H20-I20 -> 0 | N20: =K20-L20-M20 -> 0 | R20: =O20-P20-Q20 -> 0 | V20: =S20-T20-U20 -> 0 | Z20: =W20-X20-Y20 -> 0 | AD20: =AA20-AB20-AC20 -> 0 | AH20: =AE20-AF20-AG20 -> 0 | AL20: =AI20-AJ20-AK20 -> 0 | AP20: =AM20-AN20-AO20 -> 0 | AT20: =AQ20-AR20-AS20 -> 0 | AX20: =AU20-AV20-AW20 -> 0 | BB20: =AY20-AZ20-BA20 -> 0 | BF20: =BC20-BD20-BE20 -> 0 | BJ20: =BG20-BH20-BI20 -> 0 | BN20: =BK20-BL20-BM20 -> 0 | BR20: =BO20-BP20-BQ20 -> 0
F21: =C21-D21-E21 -> 0 | J21: =G21-H21-I21 -> 0 | N21: =K21-L21-M21 -> 0 | R21: =O21-P21-Q21 -> 0 | V21: =S21-T21-U21 -> 0 | Z21: =W21-X21-Y21 -> 0 | AD21: =AA21-AB21-AC21 -> 0 | AH21: =AE21-AF21-AG21 -> 0 | AL21: =AI21-AJ21-AK21 -> 0 | AP21: =AM21-AN21-AO21 -> 0 | AT21: =AQ21-AR21-AS21 -> 0 | AX21: =AU21-AV21-AW21 -> 0 | BB21: =AY21-AZ21-BA21 -> 0 | BF21: =BC21-BD21-BE21 -> 0 | BJ21: =BG21-BH21-BI21 -> 0 | BN21: =BK21-BL21-BM21 -> 0 | BR21: =BO21-BP21-BQ21 -> 0
F22: =C22-D22-E22 -> 0 | J22: =G22-H22-I22 -> 0 | N22: =K22-L22-M22 -> 0 | R22: =O22-P22-Q22 -> 0 | V22: =S22-T22-U22 -> 0 | Z22: =W22-X22-Y22 -> 0 | AD22: =AA22-AB22-AC22 -> 0 | AH22: =AE22-AF22-AG22 -> 0 | AL22: =AI22-AJ22-AK22 -> 0 | AP22: =AM22-AN22-AO22 -> 0 | AT22: =AQ22-AR22-AS22 -> 0 | AX22: =AU22-AV22-AW22 -> 0 | BB22: =AY22-AZ22-BA22 -> 0 | BF22: =BC22-BD22-BE22 -> 0 | BJ22: =BG22-BH22-BI22 -> 0 | BN22: =BK22-BL22-BM22 -> 0 | BR22: =BO22-BP22-BQ22 -> 0
... F30: =C30-D30-E30 -> 0 | J30: =G30-H30-I30 -> 0 | N30: =K30-L30-M30 -> 0 | R30: =O30-P30-Q30 -> 0 | V30: =S30-T30-U30 -> 0 | Z30: =W30-X30-Y30 -> 0 | AD30: =AA30-AB30-AC30 -> 0 | AH30: =AE30-AF30-AG30 -> 0 | AL30: =AI30-AJ30-AK30 -> 0 | AP30: =AM30-AN30-AO30 -> 0 | AT30: =AQ30-AR30-AS30 -> 0 | AX30: =AU30-AV30-AW30 -> 0 | BB30: =AY30-AZ30-BA30 -> 0 | BF30: =BC30-BD30-BE30 -> 0 | BJ30: =BG30-BH30-BI30 -> 0 | BN30: =BK30-BL30-BM30 -> 0 | BR30: =BO30-BP30-BQ30 -> 0
B31: TOTAL | C31: =SUM(C11:C30) -> 0 | D31: =SUM(D11:D30) -> 0 | E31: =SUM(E11:E30) -> 0 | F31: =SUM(F11:F30) -> 0 | G31: =SUM(G11:G30) -> 0 | H31: =SUM(H11:H30) -> 0 | I31: =SUM(I11:I30) -> 0 | J31: =SUM(J11:J30) -> 0 | ... BR31: =SUM(BR11:BR30) -> 0
C35: ='01'!C35:F35 -> Ovo 1 L | G35: ='01'!G35:J35 -> Gema 1 L | K35: ='01'!K35:N35 -> Clara 1L | O35: ='01'!O35:R35 -> Pão de Queijo 1 Kg | S35: ='01'!S35:V35 -> Pão de Queijo 2 Kg | W35: ='01'!W35:Z35 -> PQ Requeijão | AA35: ='01'!AA35:AD35 -> PQ Requeijão 4kg | AE35: ='01'!AE35:AH35 -> PQ Frango | AI35: ='01'!AI35:AL35 -> PQ Calabresa | AM35: ='01'!AM35:AP35 -> PQ Goiabada | AQ35: ='01'!AQ35:AT35 -> PQ Doce de Leite | AU35: ='01'!AU35:AX35 -> PQ Pizza | AY35: ='01'!AY35:BB35 -> TP MM BRANCO | BC35: ='01'!BC35:BF35 -> TP MM ROSA | BG35: ='01'!BG35:BJ35 -> TPC MM | BK35: ='01'!BK35:BN35 -> DESMOLDANTE 1L | BO35: ='01'!BO35:BR35 -> Melo Dito
C36: Estoque Inicial | E36: ='01'!E41:F41 -> 0 | G36: Estoque Inicial | I36: ='01'!I41:J41 -> 0 | K36: Estoque Inicial | M36: ='01'!M41:N41 -> 0 | O36: Estoque Inicial | Q36: ='01'!Q41:R41 -> 0 | S36: Estoque Inicial | U36: ='01'!U41:V41 -> 0 | W36: Estoque Inicial | Y36: ='01'!Y41:Z41 -> 0 | AA36: Estoque Inicial | AC36: ='01'!AC41:AD41 -> 0 | AE36: Estoque Inicial | AG36: ='01'!AG41:AH41 -> 0 | AI36: Estoque Inicial | AK36: ='01'!AK41:AL41 -> 0 | AM36: Estoque Inicial | AO36: ='01'!AO41:AP41 -> 0 | AQ36: Estoque Inicial | AS36: ='01'!AS41:AT41 -> 0 | AU36: Estoque Inicial | AW36: ='01'!AW41:AX41 -> 0 | AY36: Estoque Inicial | BA36: ='01'!BA41:BB41 -> 0 | BC36: Estoque Inicial | BE36: ='01'!BE41:BF41 -> 0 | BG36: Estoque Inicial | BI36: ='01'!BI41:BJ41 -> 0 | BK36: Estoque Inicial | BM36: ='01'!BM41:BN41 -> 0 | BO36: Estoque Inicial | BQ36: ='01'!BQ41:BR41 -> 0
C37: Saída | E37: =-C64 -> 0 | G37: Saída | I37: =-G64 -> 0 | K37: Saída | M37: =-K64 -> 0 | O37: Saída | Q37: =-O64 -> 0 | S37: Saída | U37: =-S64 -> 0 | W37: Saída | Y37: =-W64 -> 0 | AA37: Saída | AC37: =-AA64 -> 0 | AE37: Saída | AG37: =-AE64 -> 0 | AI37: Saída | AK37: =-AI64 -> 0 | AM37: Saída | AO37: =-AM64 -> 0 | AQ37: Saída | AS37: =-AQ64 -> 0 | AU37: Saída | AW37: =-AU64 -> 0 | AY37: Saída | BA37: =-AY64 -> 0 | BC37: Saída | BE37: =-BC64 -> 0 | BG37: Saída | BI37: =-BG64 -> 0 | BK37: Saída | BM37: =-BK64 -> 0 | BO37: Saída | BQ37: =-BO64 -> 0
C38: Retorno | E38: =D64 -> 0 | G38: Retorno | I38: =H64 -> 0 | K38: Retorno | M38: =L64 -> 0 | O38: Retorno | Q38: =P64 -> 0 | S38: Retorno | U38: =T64 -> 0 | W38: Retorno | Y38: =X64 -> 0 | AA38: Retorno | AC38: =AB64 -> 0 | AE38: Retorno | AG38: =AF64 -> 0 | AI38: Retorno | AK38: =AJ64 -> 0 | AM38: Retorno | AO38: =AN64 -> 0 | AQ38: Retorno | AS38: =AR64 -> 0 | AU38: Retorno | AW38: =AV64 -> 0 | AY38: Retorno | BA38: =AZ64 -> 0 | BC38: Retorno | BE38: =BD64 -> 0 | BG38: Retorno | BI38: =BH64 -> 0 | BK38: Retorno | BM38: =BL64 -> 0 | BO38: Retorno | BQ38: =BP64 -> 0
C39: Trocas | E39: =-E64 -> 0 | G39: Trocas | I39: =-I64 -> 0 | K39: Trocas | M39: =-M64 -> 0 | O39: Trocas | Q39: =-Q64 -> 0 | S39: Trocas | U39: =-U64 -> 0 | W39: Trocas | Y39: =-Y64 -> 0 | AA39: Trocas | AC39: =-AC64 -> 0 | AE39: Trocas | AG39: =-AG64 -> 0 | AI39: Trocas | AK39: =-AK64 -> 0 | AM39: Trocas | AO39: =-AO64 -> 0 | AQ39: Trocas | AS39: =-AS64 -> 0 | AU39: Trocas | AW39: =-AW64 -> 0 | AY39: Trocas | BA39: =-BA64 -> 0 | BC39: Trocas | BE39: =-BE64 -> 0 | BG39: Trocas | BI39: =-BI64 -> 0 | BK39: Trocas | BM39: =-BM64 -> 0 | BO39: Trocas | BQ39: =-BQ64 -> 0
C40: Compra / Entrega | G40: Compra / Entrega | K40: Compra / Entrega | O40: Compra / Entrega | S40: Compra / Entrega | W40: Compra / Entrega | AA40: Compra / Entrega | AE40: Compra / Entrega | AI40: Compra / Entrega | AM40: Compra / Entrega | AQ40: Compra / Entrega | AU40: Compra / Entrega | AY40: Compra / Entrega | BC40: Compra / Entrega | BG40: Compra / Entrega | BK40: Compra / Entrega | BO40: Compra / Entrega
C41: Estoque Atual | E41: =SUM(E36:E40) -> 0 | G41: Estoque Atual | I41: =SUM(I36:I40) -> 0 | K41: Estoque Atual | M41: =SUM(M36:M40) -> 0 | O41: Estoque Atual | Q41: =SUM(Q36:Q40) -> 0 | S41: Estoque Atual | U41: =SUM(U36:U40) -> 0 | W41: Estoque Atual | Y41: =SUM(Y36:Y40) -> 0 | AA41: Estoque Atual | AC41: =SUM(AC36:AC40) -> 0 | AE41: Estoque Atual | AG41: =SUM(AG36:AG40) -> 0 | AI41: Estoque Atual | AK41: =SUM(AK36:AK40) -> 0 | AM41: Estoque Atual | AO41: =SUM(AO36:AO40) -> 0 | AQ41: Estoque Atual | AS41: =SUM(AS36:AS40) -> 0 | AU41: Estoque Atual | AW41: =SUM(AW36:AW40) -> 0 | AY41: Estoque Atual | BA41: =SUM(BA36:BA40) -> 0 | BC41: Estoque Atual | BE41: =SUM(BE36:BE40) -> 0 | BG41: Estoque Atual | BI41: =SUM(BI36:BI40) -> 0 | BK41: Estoque Atual | BM41: =SUM(BM36:BM40) -> 0 | BO41: Estoque Atual | BQ41: =SUM(BQ36:BQ40) -> 0
B43: Vendedor | C43: Saída | D43: Retorno | E43: Trocas | F43: Vendas | G43: Saída | H43: Retorno | I43: Trocas | J43: Vendas | K43: Saída | L43: Retorno | M43: Trocas | N43: Vendas | O43: Saída | P43: Retorno | Q43: Trocas | R43: Vendas | S43: Saída | T43: Retorno | U43: Trocas | V43: Vendas | W43: Saída | X43: Retorno | Y43: Trocas | Z43: Vendas | AA43: Saída | AB43: Retorno | AC43: Trocas | AD43: Vendas | AE43: Saída | AF43: Retorno | AG43: Trocas | AH43: Vendas | AI43: Saída | AJ43: Retorno | AK43: Trocas | AL43: Vendas | AM43: Saída | AN43: Retorno | AO43: Trocas | AP43: Vendas | AQ43: Saída | AR43: Retorno | AS43: Trocas | AT43: Vendas | AU43: Saída | AV43: Retorno | AW43: Trocas | AX43: Vendas | AY43: Saída | AZ43: Retorno | BA43: Trocas | BB43: Vendas | BC43: Saída | BD43: Retorno | BE43: Trocas | BF43: Vendas | BG43: Saída | BH43: Retorno | BI43: Trocas | BJ43: Vendas | BK43: Saída | BL43: Retorno | BM43: Trocas | BN43: Vendas | BO43: Saída | BP43: Retorno | BQ43: Trocas | BR43: Vendas
B44: =B11 -> 0 | F44: =C44-D44-E44 -> 0 | J44: =G44-H44-I44 -> 0 | N44: =K44-L44-M44 -> 0 | R44: =O44-P44-Q44 -> 0 | V44: =S44-T44-U44 -> 0 | Z44: =W44-X44-Y44 -> 0 | AD44: =AA44-AB44-AC44 -> 0 | AH44: =AE44-AF44-AG44 -> 0 | AL44: =AI44-AJ44-AK44 -> 0 | AP44: =AM44-AN44-AO44 -> 0 | AT44: =AQ44-AR44-AS44 -> 0 | AX44: =AU44-AV44-AW44 -> 0 | BB44: =AY44-AZ44-BA44 -> 0 | BF44: =BC44-BD44-BE44 -> 0 | BJ44: =BG44-BH44-BI44 -> 0 | BN44: =BK44-BL44-BM44 -> 0 | BR44: =BO44-BP44-BQ44 -> 0
B45: =B12 -> 0 | F45: =C45-D45-E45 -> 0 | J45: =G45-H45-I45 -> 0 | N45: =K45-L45-M45 -> 0 | R45: =O45-P45-Q45 -> 0 | V45: =S45-T45-U45 -> 0 | Z45: =W45-X45-Y45 -> 0 | AD45: =AA45-AB45-AC45 -> 0 | AH45: =AE45-AF45-AG45 -> 0 | AL45: =AI45-AJ45-AK45 -> 0 | AP45: =AM45-AN45-AO45 -> 0 | AT45: =AQ45-AR45-AS45 -> 0 | AX45: =AU45-AV45-AW45 -> 0 | BB45: =AY45-AZ45-BA45 -> 0 | BF45: =BC45-BD45-BE45 -> 0 | BJ45: =BG45-BH45-BI45 -> 0 | BN45: =BK45-BL45-BM45 -> 0 | BR45: =BO45-BP45-BQ45 -> 0
B46: =B13 -> 0 | F46: =C46-D46-E46 -> 0 | J46: =G46-H46-I46 -> 0 | N46: =K46-L46-M46 -> 0 | R46: =O46-P46-Q46 -> 0 | V46: =S46-T46-U46 -> 0 | Z46: =W46-X46-Y46 -> 0 | AD46: =AA46-AB46-AC46 -> 0 | AH46: =AE46-AF46-AG46 -> 0 | AL46: =AI46-AJ46-AK46 -> 0 | AP46: =AM46-AN46-AO46 -> 0 | AT46: =AQ46-AR46-AS46 -> 0 | AX46: =AU46-AV46-AW46 -> 0 | BB46: =AY46-AZ46-BA46 -> 0 | BF46: =BC46-BD46-BE46 -> 0 | BJ46: =BG46-BH46-BI46 -> 0 | BN46: =BK46-BL46-BM46 -> 0 | BR46: =BO46-BP46-BQ46 -> 0
B47: =B14 -> 0 | F47: =C47-D47-E47 -> 0 | J47: =G47-H47-I47 -> 0 | N47: =K47-L47-M47 -> 0 | R47: =O47-P47-Q47 -> 0 | V47: =S47-T47-U47 -> 0 | Z47: =W47-X47-Y47 -> 0 | AD47: =AA47-AB47-AC47 -> 0 | AH47: =AE47-AF47-AG47 -> 0 | AL47: =AI47-AJ47-AK47 -> 0 | AP47: =AM47-AN47-AO47 -> 0 | AT47: =AQ47-AR47-AS47 -> 0 | AX47: =AU47-AV47-AW47 -> 0 | BB47: =AY47-AZ47-BA47 -> 0 | BF47: =BC47-BD47-BE47 -> 0 | BJ47: =BG47-BH47-BI47 -> 0 | BN47: =BK47-BL47-BM47 -> 0 | BR47: =BO47-BP47-BQ47 -> 0
B48: =B15 -> 0 | F48: =C48-D48-E48 -> 0 | J48: =G48-H48-I48 -> 0 | N48: =K48-L48-M48 -> 0 | R48: =O48-P48-Q48 -> 0 | V48: =S48-T48-U48 -> 0 | Z48: =W48-X48-Y48 -> 0 | AD48: =AA48-AB48-AC48 -> 0 | AH48: =AE48-AF48-AG48 -> 0 | AL48: =AI48-AJ48-AK48 -> 0 | AP48: =AM48-AN48-AO48 -> 0 | AT48: =AQ48-AR48-AS48 -> 0 | AX48: =AU48-AV48-AW48 -> 0 | BB48: =AY48-AZ48-BA48 -> 0 | BF48: =BC48-BD48-BE48 -> 0 | BJ48: =BG48-BH48-BI48 -> 0 | BN48: =BK48-BL48-BM48 -> 0 | BR48: =BO48-BP48-BQ48 -> 0
B49: =B16 -> 0 | F49: =C49-D49-E49 -> 0 | J49: =G49-H49-I49 -> 0 | N49: =K49-L49-M49 -> 0 | R49: =O49-P49-Q49 -> 0 | V49: =S49-T49-U49 -> 0 | Z49: =W49-X49-Y49 -> 0 | AD49: =AA49-AB49-AC49 -> 0 | AH49: =AE49-AF49-AG49 -> 0 | AL49: =AI49-AJ49-AK49 -> 0 | AP49: =AM49-AN49-AO49 -> 0 | AT49: =AQ49-AR49-AS49 -> 0 | AX49: =AU49-AV49-AW49 -> 0 | BB49: =AY49-AZ49-BA49 -> 0 | BF49: =BC49-BD49-BE49 -> 0 | BJ49: =BG49-BH49-BI49 -> 0 | BN49: =BK49-BL49-BM49 -> 0 | BR49: =BO49-BP49-BQ49 -> 0
B50: =B17 -> 0 | F50: =C50-D50-E50 -> 0 | J50: =G50-H50-I50 -> 0 | N50: =K50-L50-M50 -> 0 | R50: =O50-P50-Q50 -> 0 | V50: =S50-T50-U50 -> 0 | Z50: =W50-X50-Y50 -> 0 | AD50: =AA50-AB50-AC50 -> 0 | AH50: =AE50-AF50-AG50 -> 0 | AL50: =AI50-AJ50-AK50 -> 0 | AP50: =AM50-AN50-AO50 -> 0 | AT50: =AQ50-AR50-AS50 -> 0 | AX50: =AU50-AV50-AW50 -> 0 | BB50: =AY50-AZ50-BA50 -> 0 | BF50: =BC50-BD50-BE50 -> 0 | BJ50: =BG50-BH50-BI50 -> 0 | BN50: =BK50-BL50-BM50 -> 0 | BR50: =BO50-BP50-BQ50 -> 0
B51: =B18 -> 0 | F51: =C51-D51-E51 -> 0 | J51: =G51-H51-I51 -> 0 | N51: =K51-L51-M51 -> 0 | R51: =O51-P51-Q51 -> 0 | V51: =S51-T51-U51 -> 0 | Z51: =W51-X51-Y51 -> 0 | AD51: =AA51-AB51-AC51 -> 0 | AH51: =AE51-AF51-AG51 -> 0 | AL51: =AI51-AJ51-AK51 -> 0 | AP51: =AM51-AN51-AO51 -> 0 | AT51: =AQ51-AR51-AS51 -> 0 | AX51: =AU51-AV51-AW51 -> 0 | BB51: =AY51-AZ51-BA51 -> 0 | BF51: =BC51-BD51-BE51 -> 0 | BJ51: =BG51-BH51-BI51 -> 0 | BN51: =BK51-BL51-BM51 -> 0 | BR51: =BO51-BP51-BQ51 -> 0
B52: =B19 -> 0 | F52: =C52-D52-E52 -> 0 | J52: =G52-H52-I52 -> 0 | N52: =K52-L52-M52 -> 0 | R52: =O52-P52-Q52 -> 0 | V52: =S52-T52-U52 -> 0 | Z52: =W52-X52-Y52 -> 0 | AD52: =AA52-AB52-AC52 -> 0 | AH52: =AE52-AF52-AG52 -> 0 | AL52: =AI52-AJ52-AK52 -> 0 | AP52: =AM52-AN52-AO52 -> 0 | AT52: =AQ52-AR52-AS52 -> 0 | AX52: =AU52-AV52-AW52 -> 0 | BB52: =AY52-AZ52-BA52 -> 0 | BF52: =BC52-BD52-BE52 -> 0 | BJ52: =BG52-BH52-BI52 -> 0 | BN52: =BK52-BL52-BM52 -> 0 | BR52: =BO52-BP52-BQ52 -> 0
B53: =B20 -> 0 | F53: =C53-D53-E53 -> 0 | J53: =G53-H53-I53 -> 0 | N53: =K53-L53-M53 -> 0 | R53: =O53-P53-Q53 -> 0 | V53: =S53-T53-U53 -> 0 | Z53: =W53-X53-Y53 -> 0 | AD53: =AA53-AB53-AC53 -> 0 | AH53: =AE53-AF53-AG53 -> 0 | AL53: =AI53-AJ53-AK53 -> 0 | AP53: =AM53-AN53-AO53 -> 0 | AT53: =AQ53-AR53-AS53 -> 0 | AX53: =AU53-AV53-AW53 -> 0 | BB53: =AY53-AZ53-BA53 -> 0 | BF53: =BC53-BD53-BE53 -> 0 | BJ53: =BG53-BH53-BI53 -> 0 | BN53: =BK53-BL53-BM53 -> 0 | BR53: =BO53-BP53-BQ53 -> 0
...

Sheet 03
C2: ='01'!C2:F2 -> Litros | G2: ='01'!G2:J2 -> Mini | K2: ='01'!K2:N2 -> Molho | O2: ='01'!O2:R2 -> Tetra Pak | S2: ='01'!S2:V2 -> TP Culinário | W2: ='01'!W2:Z2 -> Coco Fresco 250g | AA2: ='01'!AA2:AD2 -> Coco Fresco 500g | AE2: ='01'!AE2:AH2 -> Coco Fresco 1kg | AI2: ='01'!AI2:AL2 -> Coco Fresco Fino 500g | AM2: ='01'!AM2:AP2 -> Coco Fresco Puro 1kg | AQ2: ='01'!AQ2:AT2 -> Coco Seco Fino 500g | AU2: ='01'!AU2:AX2 -> Coco Seco Flocos 500g | AY2: ='01'!AY2:BB2 -> Marshmallow 1Kg | BC2: ='01'!BC2:BF2 -> Marshmallow 500g | BG2: ='01'!BG2:BJ2 -> Massa Folhada 1Kg | BK2: ='01'!BK2:BN2 -> Massa Folhada 2,2Kg | BO2: ='01'!BO2:BR2 -> Massa Semi-Folhada 2Kg
C3: Estoque Inicial | E3: ='02'!E8:F8 -> 0 | G3: Estoque Inicial | I3: ='02'!I8:J8 -> 0 | K3: Estoque Inicial | M3: ='02'!M8:N8 -> 0 | O3: Estoque Inicial | Q3: ='02'!Q8:R8 -> 0 | S3: Estoque Inicial | U3: ='02'!U8:V8 -> 0 | W3: Estoque Inicial | Y3: ='02'!Y8:Z8 -> 0 | AA3: Estoque Inicial | AC3: ='02'!AC8:AD8 -> 0 | AE3: Estoque Inicial | AG3: ='02'!AG8:AH8 -> 0 | AI3: Estoque Inicial | AK3: ='02'!AK8:AL8 -> 0 | AM3: Estoque Inicial | AO3: ='02'!AO8:AP8 -> 0 | AQ3: Estoque Inicial | AS3: ='02'!AS8:AT8 -> 0 | AU3: Estoque Inicial | AW3: ='02'!AW8:AX8 -> 0 | AY3: Estoque Inicial | BA3: ='02'!BA8:BB8 -> 0 | BC3: Estoque Inicial | BE3: ='02'!BE8:BF8 -> 0 | BG3: Estoque Inicial | BI3: ='02'!BI8:BJ8 -> 0 | BK3: Estoque Inicial | BM3: ='02'!BM8:BN8 -> 0 | BO3: Estoque Inicial | BQ3: ='02'!BQ8:BR8 -> 0
C4: Saída | E4: =-C31 -> 0 | G4: Saída | I4: =-G31 -> 0 | K4: Saída | M4: =-K31 -> 0 | O4: Saída | Q4: =-O31 -> 0 | S4: Saída | U4: =-S31 -> 0 | W4: Saída | Y4: =-W31 -> 0 | AA4: Saída | AC4: =-AA31 -> 0 | AE4: Saída | AG4: =-AE31 -> 0 | AI4: Saída | AK4: =-AI31 -> 0 | AM4: Saída | AO4: =-AM31 -> 0 | AQ4: Saída | AS4: =-AQ31 -> 0 | AU4: Saída | AW4: =-AU31 -> 0 | AY4: Saída | BA4: =-AY31 -> 0 | BC4: Saída | BE4: =-BC31 -> 0 | BG4: Saída | BI4: =-BG31 -> 0 | BK4: Saída | BM4: =-BK31 -> 0 | BO4: Saída | BQ4: =-BO31 -> 0
C5: Retorno | E5: =D31 -> 0 | G5: Retorno | I5: =H31 -> 0 | K5: Retorno | M5: =L31 -> 0 | O5: Retorno | Q5: =P31 -> 0 | S5: Retorno | U5: =T31 -> 0 | W5: Retorno | Y5: =X31 -> 0 | AA5: Retorno | AC5: =AB31 -> 0 | AE5: Retorno | AG5: =AF31 -> 0 | AI5: Retorno | AK5: =AJ31 -> 0 | AM5: Retorno | AO5: =AN31 -> 0 | AQ5: Retorno | AS5: =AR31 -> 0 | AU5: Retorno | AW5: =AV31 -> 0 | AY5: Retorno | BA5: =AZ31 -> 0 | BC5: Retorno | BE5: =BD31 -> 0 | BG5: Retorno | BI5: =BH31 -> 0 | BK5: Retorno | BM5: =BL31 -> 0 | BO5: Retorno | BQ5: =BP31 -> 0
C6: Trocas | E6: =-E31 -> 0 | G6: Trocas | I6: =-I31 -> 0 | K6: Trocas | M6: =-M31 -> 0 | O6: Trocas | Q6: =-Q31 -> 0 | S6: Trocas | U6: =-U31 -> 0 | W6: Trocas | Y6: =-Y31 -> 0 | AA6: Trocas | AC6: =-AC31 -> 0 | AE6: Trocas | AG6: =-AG31 -> 0 | AI6: Trocas | AK6: =-AK31 -> 0 | AM6: Trocas | AO6: =-AO31 -> 0 | AQ6: Trocas | AS6: =-AS31 -> 0 | AU6: Trocas | AW6: =-AW31 -> 0 | AY6: Trocas | BA6: =-BA31 -> 0 | BC6: Trocas | BE6: =-BE31 -> 0 | BG6: Trocas | BI6: =-BI31 -> 0 | BK6: Trocas | BM6: =-BM31 -> 0 | BO6: Trocas | BQ6: =-BQ31 -> 0
C7: Produção | G7: Produção | K7: Produção | O7: Compra / Entrega | S7: Compra / Entrega | W7: Compra / Entrega | AA7: Compra / Entrega | AE7: Compra / Entrega | AI7: Compra / Entrega | AM7: Compra / Entrega | AQ7: Compra / Entrega | AU7: Compra / Entrega | AY7: Compra / Entrega | BC7: Compra / Entrega | BG7: Compra / Entrega | BK7: Compra / Entrega | BO7: Compra / Entrega
C8: Estoque Atual | E8: =SUM(E3:E7) -> 0 | G8: Estoque Atual | I8: =SUM(I3:I7) -> 0 | K8: Estoque Atual | M8: =SUM(M3:M7) -> 0 | O8: Estoque Atual | Q8: =SUM(Q3:Q7) -> 0 | S8: Estoque Atual | U8: =SUM(U3:U7) -> 0 | W8: Estoque Atual | Y8: =SUM(Y3:Y7) -> 0 | AA8: Estoque Atual | AC8: =SUM(AC3:AC7) -> 0 | AE8: Estoque Atual | AG8: =SUM(AG3:AG7) -> 0 | AI8: Estoque Atual | AK8: =SUM(AK3:AK7) -> 0 | AM8: Estoque Atual | AO8: =SUM(AO3:AO7) -> 0 | AQ8: Estoque Atual | AS8: =SUM(AS3:AS7) -> 0 | AU8: Estoque Atual | AW8: =SUM(AW3:AW7) -> 0 | AY8: Estoque Atual | BA8: =SUM(BA3:BA7) -> 0 | BC8: Estoque Atual | BE8: =SUM(BE3:BE7) -> 0 | BG8: Estoque Atual | BI8: =SUM(BI3:BI7) -> 0 | BK8: Estoque Atual | BM8: =SUM(BM3:BM7) -> 0 | BO8: Estoque Atual | BQ8: =SUM(BQ3:BQ7) -> 0
B10: Vendedor | C10: Saída | D10: Retorno | E10: Trocas | F10: Vendas | G10: Saída | H10: Retorno | I10: Trocas | J10: Vendas | K10: Saída | L10: Retorno | M10: Trocas | N10: Vendas | O10: Saída | P10: Retorno | Q10: Trocas | R10: Vendas | S10: Saída | T10: Retorno | U10: Trocas | V10: Vendas | W10: Saída | X10: Retorno | Y10: Trocas | Z10: Vendas | AA10: Saída | AB10: Retorno | AC10: Trocas | AD10: Vendas | AE10: Saída | AF10: Retorno | AG10: Trocas | AH10: Vendas | AI10: Saída | AJ10: Retorno | AK10: Trocas | AL10: Vendas | AM10: Saída | AN10: Retorno | AO10: Trocas | AP10: Vendas | AQ10: Saída | AR10: Retorno | AS10: Trocas | AT10: Vendas | AU10: Saída | AV10: Retorno | AW10: Trocas | AX10: Vendas | AY10: Saída | AZ10: Retorno | BA10: Trocas | BB10: Vendas | BC10: Saída | BD10: Retorno | BE10: Trocas | BF10: Vendas | BG10: Saída | BH10: Retorno | BI10: Trocas | BJ10: Vendas | BK10: Saída | BL10: Retorno | BM10: Trocas | BN10: Vendas | BO10: Saída | BP10: Retorno | BQ10: Trocas | BR10: Vendas
